Workbook
Name BR: [1]Module_Arr!$C$3:$C$17
Name BR: Module_Arr!$C$3:$C$18
Name BR: [1]Module_Arr!$C$3:$C$17
Name BR: [1]Module_Arr!$C$3:$C$17
Name BR: [2]Module_Arr!$C$3:$C$17
Name Cylinders: '[3]I_O functional list'!$B$2
Name Cylinders: '[3]I_O functional list'!$B$2
Name Cylinders: '[3]I_O functional list'!$B$2
Name Cylinders: '[3]I_O functional list'!$B$2
Name Cylinders: '[4]I_O functional list'!$B$2

Sheet History
A1: * 축약어 참고 MOCSAbbreviations.xlsx
A2: * I 열 Unit 행, J 열 Variable Name 행은 SW 변수 생성용 - 지제시에서만 편집
A3: Ver | B3: Date | C3: Description
A4: R0.07 | B4: 26.05.28 | C4: MSC 실선 검증용 추가 센서 반영(No.# Module) 1. 온도 센서 1개 삭제: MOCS Inlet Temp 2. 압력 센서 4개 삭제: SCR Bypass Inlet Press (PT), SCR Bypass Inlet Press (PI), Engine Turbocharger Outlet Press (PT), Engine Turbocharger Outlet Press (PI) 3. 압력 센서 3개 추가: Engine Outlet Press, MOCS Outlet Press, MOCS Inlet Press
A5: R0.06 | B5: 26.04.30 | C5: MSC 실선 검증용 추가 센서 반영(No.# Module) 1. 온도센서 5개 추가: MOCS OuletTemp, MOCS Inlet Temp, Engine Turbocharger Outlet Temp, SCR bypass inlet temp. sensor, SCR bypass outlet temp. sensor 2. 암력센서 4개 추가: SCR Bypass Inlet Press (PT), SCR Bypass Inlet Press (PI), Engine Turbocharger Outlet Press (PT), Engine Turbocharger Outlet Press (PI)
A6: R0.05 | B6: 26.03.31 | C6: 1. Common Module Sheet DI1 ch.3 Low Sulfur fuel supplied (S=0.1%) Threhold, Delay 추가 2. Common Module Sheet DI1 ch.11, 14, 15 Threhold, Delay 추가
A7: R0.04 | B7: 26.03.31 | C7: 1. I 열 Unit 행 MOCS/FODS/SCR 로 구분 2. J 열 Variable Name 행 추가(AS 변수명으로 사용) 3. No.# Module Sheet DI1 ch.16 No.# SCR Flush Run 임시 반영 3. No.# Module Sheet DO1 ch.14 No.# All Flow Through SCR 임시 반영

Sheet LP MOCS 구성
B2: with FODS
B3: 필요 I/O 개수 | J3: MOCS HW Configuration
B4: common(F.O. Supply Unit) | J4: 모듈 | K4: 모델명 | L4: Common | M4: No.# 기준 댓수 | N4: 총 필요 모듈 수 (Common+No.#)
C5: 총 접점 | D5: 사용 | E5: 접점여분 | F5: 필요 모듈 수 | G5: 여분 모듈 수 | H5: 합계 | M5: 6
B6: DI | C6: =F6*16 -> 16 | D6: =COUNTIF('Common module'!F:F,"DI") -> 15 | E6: =C6-D6 -> 1 | F6: 1 | G6: 0 | H6: =F6+G6 -> 1 | J6: CPU | K6: 1686x | L6: 1 | M6: - | N6: =L6 -> 1
B7: DO | C7: =F7*16 -> 16 | D7: =COUNTIF('Common module'!F:F,"DO") -> 7 | E7: =C7-D7 -> 9 | F7: 1 | G7: 0 | H7: =F7+G7 -> 1 | J7: Serial Comm | K7: CS1030 | L7: 1 | M7: - | N7: =L7 -> 1
B8: AI | C8: =F8*8 -> 8 | D8: =COUNTIF('Common module'!F:F,"AI") -> 2 | E8: =C8-D8 -> 6 | F8: 1 | G8: 0 | H8: =F8+G8 -> 1 | J8: power supply | K8: PS9400 | L8: - | M8: =IF(M$5>1,1,0) -> 1 | N8: =M8 -> 1
B9: AO | C9: =F9*4 -> 4 | D9: =COUNTIF('Common module'!F:F,"AO") -> 2 | E9: =C9-D9 -> 2 | F9: 1 | G9: 0 | H9: =F9+G9 -> 1 | J9: power supply | K9: PS3300 | L9: - | M9: =IF(M$5>5,2,IF(M$5>3,1,0)) -> 2 | N9: =M9 -> 2
B10: No.#(F.O Dosing Unit + Chamber Unit) | J10: buscontroller | K10: BC0083 | L10: - | M10: =IF(M$5>5,2,IF(M$5>2,1,0)) -> 2 | N10: =M10 -> 2
C11: 총 접점 | D11: 사용 | E11: 접점여분 | F11: 필요 모듈 수 | G11: 여분 모듈 수 | H11: 합계 | J11: Power Link Cable | L11: - | M11: =IF(M$5>5,2,IF(M$5>2,1,0)) -> 2 | N11: =M11 -> 2
B12: DI | C12: =F12*16 -> 16 | D12: =COUNTIF('No.# Module'!F:F,"DI") -> 15 | E12: =C12-D12 -> 1 | F12: 1 | G12: 0 | H12: =F12+G12 -> 1 | J12: DI | K12: DIF371 | L12: =H6 -> 1 | M12: =H12*M$5 -> 6 | N12: =M12+L12 -> 7
B13: DO | C13: =F13*16 -> 16 | D13: =COUNTIF('No.# Module'!F:F,"DO") -> 13 | E13: =C13-D13 -> 3 | F13: 1 | G13: 0 | H13: =F13+G13 -> 1 | J13: DO | K13: DOF322 | L13: =H7 -> 1 | M13: =H13*M$5 -> 6 | N13: =M13+L13 -> 7
B14: AI | C14: =F14*8 -> 24 | D14: =COUNTIF('No.# Module'!F:F,"AI") -> 22 | E14: =C14-D14 -> 2 | F14: 3 | G14: 0 | H14: =F14+G14 -> 3 | J14: AI | K14: AI8321 | L14: =H8 -> 1 | M14: =H14*M$5 -> 18 | N14: =M14+L14 -> 19
B15: AO | C15: =F15*4 -> 4 | D15: =COUNTIF('No.# Module'!F:F,"AO") -> 2 | E15: =C15-D15 -> 2 | F15: 1 | G15: 0 | H15: =F15+G15 -> 1 | J15: AO | K15: AO4622 | L15: =H9 -> 1 | M15: =H15*M$5 -> 6 | N15: =M15+L15 -> 7
J16: hub | K16: 0AC808.9-1 | L16: 1 | M16: - | N16: =L16 -> 1
B17: ※ 개별에 AI 신호 여분이 1개로 추후 부족할 수 있으므로 여분으로 AI 모듈 추가. | J17: HMI | K17: Beijer HMI | L17: 1 | M17: - | N17: =L17 -> 1
J18: ※ power supply는 DO모듈 2대당 1대
J19: ※ 총 필요 모듈은 MOCS 3개 기준(최대 8대까지 확장 가능)
J20: ※Common은 공통 제어 부분으로 엔진 대수와 상관없이 1세트 필요함.
B21: without FODS
B22: 필요 I/O 개수 | J22: MOCS HW Configuration
B23: common(F.O. Supply Unit) | J23: 모듈 | K23: 모델명 | L23: Common | M23: No.# 기준 댓수 | N23: 총 필요 모듈 수 (Common+No.#)
C24: 총 접점 | D24: 사용 | E24: 접점여분 | F24: 필요 모듈 수 | G24: 여분 모듈 수 | H24: 합계 | M24: 6
B25: DI | C25: =F25*16 -> 16 | D25: =COUNTIFS('Common module'!F:F,"DI",'Common module'!I:I,"common") -> 0 | E25: =C25-D25 -> 16 | F25: 1 | G25: 0 | H25: =F25+G25 -> 1 | J25: CPU | K25: 1686x | L25: 1 | M25: - | N25: =L25 -> 1
B26: DO | C26: =F26*16 -> 16 | D26: =COUNTIFS('Common module'!F:F,"DO",'Common module'!I:I,"common") -> 0 | E26: =C26-D26 -> 16 | F26: 1 | G26: 0 | H26: =F26+G26 -> 1 | J26: Serial Comm | K26: CS1030 | L26: 1 | M26: - | N26: =L26 -> 1
B27: AI | C27: =F27*8 -> 0 | D27: =COUNTIFS('Common module'!F:F,"AI",'Common module'!I:I,"common") -> 0 | E27: =C27-D27 -> 0 | F27: 0 | G27: 0 | H27: =F27+G27 -> 0 | J27: power supply | K27: PS9400 | L27: - | M27: =IF(M$24>1,1,0) -> 1 | N27: =M27 -> 1
B28: AO | C28: =F28*4 -> 0 | D28: =COUNTIFS('Common module'!F:F,"AO",'Common module'!I:I,"common") -> 0 | E28: - | F28: 0 | G28: 0 | H28: =F28+G28 -> 0 | J28: power supply | K28: PS3300 | L28: - | M28: =IF(M$24>5,2,IF(M$24>3,1,0)) -> 2 | N28: =M28 -> 2
B29: No.#(F.O Dosing Unit + Chamber Unit) | J29: buscontroller | K29: BC0083 | L29: - | M29: =IF(M$24>5,2,IF(M$24>2,1,0)) -> 2 | N29: =M29 -> 2
C30: 총 접점 | D30: 사용 | E30: 접점여분 | F30: 필요 모듈 수 | G30: 여분 모듈 수 | H30: 합계 | J30: Power Link Cable | L30: - | M30: =IF(M$24>5,2,IF(M$24>2,1,0)) -> 2 | N30: =M30 -> 2
B31: DI | C31: =F31*16 -> 16 | D31: =COUNTIFS('No.# Module'!F:F,"DI",'No.# Module'!I:I,"Individual") -> 0 | E31: =C31-D31 -> 16 | F31: 1 | G31: 0 | H31: =F31+G31 -> 1 | J31: DI | K31: DIF371 | L31: =H26 -> 1 | M31: =H32*M$24 -> 6 | N31: =M31+L31 -> 7
B32: DO | C32: =F32*16 -> 16 | D32: =COUNTIFS('No.# Module'!F:F,"DO",'No.# Module'!I:I,"Individual") -> 0 | E32: =C32-D32 -> 16 | F32: 1 | G32: 0 | H32: =F32+G32 -> 1 | J32: DO | K32: DOF322 | L32: =H27 -> 0 | M32: =H33*M$24 -> 12 | N32: =M32+L32 -> 12
B33: AI | C33: =F33*8 -> 16 | D33: =COUNTIFS('No.# Module'!F:F,"AI",'No.# Module'!I:I,"Individual") -> 0 | E33: =C33-D33 -> 16 | F33: 2 | G33: 0 | H33: =F33+G33 -> 2 | J33: AI | K33: AI8321 | L33: =H28 -> 0 | M33: =H34*M$24 -> 6 | N33: =M33+L33 -> 6
B34: AO | C34: =F34*4 -> 4 | D34: =COUNTIFS('No.# Module'!F:F,"AO",'No.# Module'!I:I,"Individual") -> 0 | E34: =C34-D34 -> 4 | F34: 1 | G34: 0 | H34: =F34+G34 -> 1 | J34: AO | K34: AO4622 | L34: =H29 -> 0 | M34: =H35*M$24 -> 0 | N34: =M34+L34 -> 0
J35: hub | K35: 0AC808.9-1 | L35: 1 | M35: - | N35: =L35 -> 1
J36: HMI | K36: Beijer HMI | L36: 1 | M36: - | N36: =L36 -> 1

Sheet Module_Arr
B1: No. | C1: Model | D1: Length | E1: Type | F1: Power consumption (W) | H1: Remark | J1: 2. 1 Door arrangement
F2: Bus | G2: IO | J2: 1) Total width | L2: 800
B3: 1 | C3: X20CP1686X | D3: 150 | E3: CPU | F3: -7.5 | J3: 2) Cable tray & Others width | L3: 300
B4: 2 | C4: X20CS1030 | D4: 12.5 | E4: RS485 | F4: -0.01 | G4: -1.44 | J4: 3) Module width | L4: 500
B5: 3 | C5: X20PS9400 | D5: 12.5 | E5: Power | F5: 7 | G5: 240
B6: 4 | C6: X20BC0083 | D6: 37.5 | E6: Bus | F6: -2 | G6: 0 | H6: Controller | J6: 3. With FODS moduel arrangement
B7: 5 | C7: X20DIF371 | D7: 12.5 | E7: DI | F7: -0.18 | G7: -1.47 | J7: 1st layer width | L7: =SUM(K10:K29) -> 381.5 | M7: (Max. 500) | S7: 2nd layer width | U7: =SUM(T10:T43) -> 450 | V7: (Max. 500)
B8: 5 | C8: X20DOF322 | D8: 12.5 | E8: DO | F8: -0.28 | G8: -95 | J8: Model | K8: Length | L8: Type | M8: Tag | N8: Power consumption | P8: Remained power | S8: Model | T8: Length | U8: Type | V8: Tag | W8: Power consumption | Y8: Remained power
B9: 6 | C9: X20AI8321 | D9: 12.5 | E9: AI | F9: -0.01 | G9: -1.37 | N9: Bus | O9: IO | P9: Bus | Q9: IO | W9: Bus | X9: IO | Y9: Bus | Z9: IO
B10: 7 | C10: X20AO4622 | D10: 12.5 | E10: AO | F10: -0.01 | G10: -1.8 | J10: X20CP1686X | K10: =IF(COUNTA(J10), VLOOKUP(J10, $C$3:$G$18, 2, 0), 0) -> 150 | L10: =IF(COUNTA(J10), VLOOKUP(J10, $C$3:$G$18, 3, 0), 0) -> CPU | M10: CPU | N10: =IF(COUNTA(J10), VLOOKUP(J10, $C$3:$G$18, 4, 0), 0) -> -7.5 | O10: =IF(COUNTA(J10), VLOOKUP(J10, $C$3:$G$18, 5, 0), 0) -> 0 | S10: X20BC0083 | T10: =IF(COUNTA(S10), VLOOKUP(S10, $C$3:$G$18, 2, 0), 0) -> 37.5 | U10: =IF(COUNTA(S10), VLOOKUP(S10, $C$3:$G$18, 3, 0), 0) -> Bus | V10: BC2 | W10: =IF(COUNTA(S10), VLOOKUP(S10, $C$3:$G$18, 4, 0), 0) -> -2 | X10: =IF(COUNTA(S10), VLOOKUP(S10, $C$3:$G$18, 5, 0), 0) -> 0
B11: 8 | C11: IE-SW-BLB-08-8TX | D11: 44 | H11: Ethernet hub, 별도 Power(2W) | K11: =IF(COUNTA(J11), VLOOKUP(J11, $C$3:$G$18, 2, 0), 0) -> 0 | L11: =IF(COUNTA(J11), VLOOKUP(J11, $C$3:$G$18, 3, 0), 0) -> 0 | N11: =IF(COUNTA(J11), VLOOKUP(J11, $C$3:$G$18, 4, 0), 0) -> 0 | O11: =IF(COUNTA(J11), VLOOKUP(J11, $C$3:$G$18, 5, 0), 0) -> 0 | S11: X20PS9400 | T11: =IF(COUNTA(S11), VLOOKUP(S11, $C$3:$E$18, 2, 0), 0) -> 12.5 | U11: =IF(COUNTA(S11), VLOOKUP(S11, $C$3:$E$18, 3, 0), 0) -> Power | V11: PS2 | W11: =IF(COUNTA(S11), VLOOKUP(S11, $C$3:$G$18, 4, 0), 0) -> 7 | X11: =IF(COUNTA(S11), VLOOKUP(S11, $C$3:$G$18, 5, 0), 0) -> 240 | Y11: =SUM(W10:W11) -> 5 | Z11: =SUM(X10:X11) -> 240
J12: X20BC0083 | K12: =IF(COUNTA(J12), VLOOKUP(J12, $C$3:$G$18, 2, 0), 0) -> 37.5 | L12: =IF(COUNTA(J12), VLOOKUP(J12, $C$3:$G$18, 3, 0), 0) -> Bus | M12: BC1 | N12: =IF(COUNTA(J12), VLOOKUP(J12, $C$3:$G$18, 4, 0), 0) -> -2 | O12: =IF(COUNTA(J12), VLOOKUP(J12, $C$3:$G$18, 5, 0), 0) -> 0 | P12: =N12+P11 -> -2 | Q12: =O12+Q11 -> 0 | S12: X20DIF371 | T12: =IF(COUNTA(S12), VLOOKUP(S12, $C$3:$E$18, 2, 0), 0) -> 12.5 | U12: =IF(COUNTA(S12), VLOOKUP(S12, $C$3:$E$18, 3, 0), 0) -> DI | V12: 2DI1 | W12: =IF(COUNTA(S12), VLOOKUP(S12, $C$3:$G$18, 4, 0), 0) -> -0.18 | X12: =IF(COUNTA(S12), VLOOKUP(S12, $C$3:$G$18, 5, 0), 0) -> -1.47 | Y12: =W12+Y11 -> 4.82 | Z12: =X12+Z11 -> 238.53
J13: X20PS9400 | K13: =IF(COUNTA(J13), VLOOKUP(J13, $C$3:$G$18, 2, 0), 0) -> 12.5 | L13: =IF(COUNTA(J13), VLOOKUP(J13, $C$3:$G$18, 3, 0), 0) -> Power | M13: PS1 | N13: =IF(COUNTA(J13), VLOOKUP(J13, $C$3:$G$18, 4, 0), 0) -> 7 | O13: =IF(COUNTA(J13), VLOOKUP(J13, $C$3:$G$18, 5, 0), 0) -> 240 | P13: =N13+P12 -> 5 | Q13: =O13+Q12 -> 240 | S13: X20DOF322 | T13: =IF(COUNTA(S13), VLOOKUP(S13, $C$3:$E$18, 2, 0), 0) -> 12.5 | U13: =IF(COUNTA(S13), VLOOKUP(S13, $C$3:$E$18, 3, 0), 0) -> DO | V13: 2DO1 | W13: =IF(COUNTA(S13), VLOOKUP(S13, $C$3:$G$18, 4, 0), 0) -> -0.28 | X13: =IF(COUNTA(S13), VLOOKUP(S13, $C$3:$G$18, 5, 0), 0) -> -95 | Y13: =W13+Y12 -> 4.54 | Z13: =X13+Z12 -> 143.53
J14: X20CS1030 | K14: =IF(COUNTA(J14), VLOOKUP(J14, $C$3:$G$18, 2, 0), 0) -> 12.5 | L14: =IF(COUNTA(J14), VLOOKUP(J14, $C$3:$G$18, 3, 0), 0) -> RS485 | M14: RS485 | N14: =IF(COUNTA(J14), VLOOKUP(J14, $C$3:$G$18, 4, 0), 0) -> -0.01 | O14: =IF(COUNTA(J14), VLOOKUP(J14, $C$3:$G$18, 5, 0), 0) -> -1.44 | P14: =N14+P13 -> 4.99 | Q14: =O14+Q13 -> 238.56 | S14: X20AI8321 | T14: =IF(COUNTA(S14), VLOOKUP(S14, $C$3:$E$18, 2, 0), 0) -> 12.5 | U14: =IF(COUNTA(S14), VLOOKUP(S14, $C$3:$E$18, 3, 0), 0) -> AI | V14: 2AI1 | W14: =IF(COUNTA(S14), VLOOKUP(S14, $C$3:$G$18, 4, 0), 0) -> -0.01 | X14: =IF(COUNTA(S14), VLOOKUP(S14, $C$3:$G$18, 5, 0), 0) -> -1.37 | Y14: =W14+Y13 -> 4.53 | Z14: =X14+Z13 -> 142.16
J15: X20DIF371 | K15: =IF(COUNTA(J15), VLOOKUP(J15, $C$3:$G$18, 2, 0), 0) -> 12.5 | L15: =IF(COUNTA(J15), VLOOKUP(J15, $C$3:$G$18, 3, 0), 0) -> DI | M15: 1CDI1 | N15: =IF(COUNTA(J15), VLOOKUP(J15, $C$3:$G$18, 4, 0), 0) -> -0.18 | O15: =IF(COUNTA(J15), VLOOKUP(J15, $C$3:$G$18, 5, 0), 0) -> -1.47 | P15: =N15+P14 -> 4.81 | Q15: =O15+Q14 -> 237.09 | S15: X20AI8321 | T15: =IF(COUNTA(S15), VLOOKUP(S15, $C$3:$E$18, 2, 0), 0) -> 12.5 | U15: =IF(COUNTA(S15), VLOOKUP(S15, $C$3:$E$18, 3, 0), 0) -> AI | V15: 2AI2 | W15: =IF(COUNTA(S15), VLOOKUP(S15, $C$3:$G$18, 4, 0), 0) -> -0.01 | X15: =IF(COUNTA(S15), VLOOKUP(S15, $C$3:$G$18, 5, 0), 0) -> -1.37 | Y15: =W15+Y14 -> 4.52 | Z15: =X15+Z14 -> 140.79
J16: X20DOF322 | K16: =IF(COUNTA(J16), VLOOKUP(J16, $C$3:$G$18, 2, 0), 0) -> 12.5 | L16: =IF(COUNTA(J16), VLOOKUP(J16, $C$3:$G$18, 3, 0), 0) -> DO | M16: 1CDO1 | N16: =IF(COUNTA(J16), VLOOKUP(J16, $C$3:$G$18, 4, 0), 0) -> -0.28 | O16: =IF(COUNTA(J16), VLOOKUP(J16, $C$3:$G$18, 5, 0), 0) -> -95 | P16: =N16+P15 -> 4.53 | Q16: =O16+Q15 -> 142.09 | S16: X20AI8321 | T16: =IF(COUNTA(S16), VLOOKUP(S16, $C$3:$E$18, 2, 0), 0) -> 12.5 | U16: =IF(COUNTA(S16), VLOOKUP(S16, $C$3:$E$18, 3, 0), 0) -> AI | V16: 2AI3 | W16: =IF(COUNTA(S16), VLOOKUP(S16, $C$3:$G$18, 4, 0), 0) -> -0.01 | X16: =IF(COUNTA(S16), VLOOKUP(S16, $C$3:$G$18, 5, 0), 0) -> -1.37 | Y16: =W16+Y15 -> 4.51 | Z16: =X16+Z15 -> 139.42
J17: X20AI8321 | K17: =IF(COUNTA(J17), VLOOKUP(J17, $C$3:$G$18, 2, 0), 0) -> 12.5 | L17: =IF(COUNTA(J17), VLOOKUP(J17, $C$3:$G$18, 3, 0), 0) -> AI | M17: 1CAI1 | N17: =IF(COUNTA(J17), VLOOKUP(J17, $C$3:$G$18, 4, 0), 0) -> -0.01 | O17: =IF(COUNTA(J17), VLOOKUP(J17, $C$3:$G$18, 5, 0), 0) -> -1.37 | P17: =N17+P16 -> 4.52 | Q17: =O17+Q16 -> 140.72 | S17: X20AO4622 | T17: =IF(COUNTA(S17), VLOOKUP(S17, $C$3:$E$18, 2, 0), 0) -> 12.5 | U17: =IF(COUNTA(S17), VLOOKUP(S17, $C$3:$E$18, 3, 0), 0) -> AO | V17: 2AO1 | W17: =IF(COUNTA(S17), VLOOKUP(S17, $C$3:$G$18, 4, 0), 0) -> -0.01 | X17: =IF(COUNTA(S17), VLOOKUP(S17, $C$3:$G$18, 5, 0), 0) -> -1.8 | Y17: =W17+Y16 -> 4.5 | Z17: =X17+Z16 -> 137.62
J18: X20AO4622 | K18: =IF(COUNTA(J18), VLOOKUP(J18, $C$3:$G$18, 2, 0), 0) -> 12.5 | L18: =IF(COUNTA(J18), VLOOKUP(J18, $C$3:$G$18, 3, 0), 0) -> AO | M18: 1DI1 | N18: =IF(COUNTA(J18), VLOOKUP(J18, $C$3:$G$18, 4, 0), 0) -> -0.01 | O18: =IF(COUNTA(J18), VLOOKUP(J18, $C$3:$G$18, 5, 0), 0) -> -1.8 | P18: =N18+P17 -> 4.51 | Q18: =O18+Q17 -> 138.92 | S18: X20DIF371 | T18: =IF(COUNTA(S18), VLOOKUP(S18, $C$3:$E$18, 2, 0), 0) -> 12.5 | U18: =IF(COUNTA(S18), VLOOKUP(S18, $C$3:$E$18, 3, 0), 0) -> DI | V18: 3DI1 | W18: =IF(COUNTA(S18), VLOOKUP(S18, $C$3:$G$18, 4, 0), 0) -> -0.18 | X18: =IF(COUNTA(S18), VLOOKUP(S18, $C$3:$G$18, 5, 0), 0) -> -1.47 | Y18: =W18+Y17 -> 4.32 | Z18: =X18+Z17 -> 136.15
J19: X20DIF371 | K19: =IF(COUNTA(J19), VLOOKUP(J19, $C$3:$G$18, 2, 0), 0) -> 12.5 | L19: =IF(COUNTA(J19), VLOOKUP(J19, $C$3:$G$18, 3, 0), 0) -> DI | M19: 1DO1 | N19: =IF(COUNTA(J19), VLOOKUP(J19, $C$3:$G$18, 4, 0), 0) -> -0.18 | O19: =IF(COUNTA(J19), VLOOKUP(J19, $C$3:$G$18, 5, 0), 0) -> -1.47 | P19: =N19+P18 -> 4.33 | Q19: =O19+Q18 -> 137.45 | S19: X20DOF322 | T19: =IF(COUNTA(S19), VLOOKUP(S19, $C$3:$E$18, 2, 0), 0) -> 12.5 | U19: =IF(COUNTA(S19), VLOOKUP(S19, $C$3:$E$18, 3, 0), 0) -> DO | V19: 3DO1 | W19: =IF(COUNTA(S19), VLOOKUP(S19, $C$3:$G$18, 4, 0), 0) -> -0.28 | X19: =IF(COUNTA(S19), VLOOKUP(S19, $C$3:$G$18, 5, 0), 0) -> -95 | Y19: =W19+Y18 -> 4.04 | Z19: =X19+Z18 -> 41.15
J20: X20DOF322 | K20: =IF(COUNTA(J20), VLOOKUP(J20, $C$3:$G$18, 2, 0), 0) -> 12.5 | L20: =IF(COUNTA(J20), VLOOKUP(J20, $C$3:$G$18, 3, 0), 0) -> DO | M20: 1AI1 | N20: =IF(COUNTA(J20), VLOOKUP(J20, $C$3:$G$18, 4, 0), 0) -> -0.28 | O20: =IF(COUNTA(J20), VLOOKUP(J20, $C$3:$G$18, 5, 0), 0) -> -95 | P20: =N20+P19 -> 4.05 | Q20: =O20+Q19 -> 42.45 | S20: X20AI8321 | T20: =IF(COUNTA(S20), VLOOKUP(S20, $C$3:$E$18, 2, 0), 0) -> 12.5 | U20: =IF(COUNTA(S20), VLOOKUP(S20, $C$3:$E$18, 3, 0), 0) -> AI | V20: 3AI1 | W20: =IF(COUNTA(S20), VLOOKUP(S20, $C$3:$G$18, 4, 0), 0) -> -0.01 | X20: =IF(COUNTA(S20), VLOOKUP(S20, $C$3:$G$18, 5, 0), 0) -> -1.37 | Y20: =W20+Y19 -> 4.03 | Z20: =X20+Z19 -> 39.78
J21: X20AI8321 | K21: =IF(COUNTA(J21), VLOOKUP(J21, $C$3:$G$18, 2, 0), 0) -> 12.5 | L21: =IF(COUNTA(J21), VLOOKUP(J21, $C$3:$G$18, 3, 0), 0) -> AI | M21: 1AI2 | N21: =IF(COUNTA(J21), VLOOKUP(J21, $C$3:$G$18, 4, 0), 0) -> -0.01 | O21: =IF(COUNTA(J21), VLOOKUP(J21, $C$3:$G$18, 5, 0), 0) -> -1.37 | P21: =N21+P20 -> 4.04 | Q21: =O21+Q20 -> 41.08 | S21: X20AI8321 | T21: =IF(COUNTA(S21), VLOOKUP(S21, $C$3:$E$18, 2, 0), 0) -> 12.5 | U21: =IF(COUNTA(S21), VLOOKUP(S21, $C$3:$E$18, 3, 0), 0) -> AI | V21: 3AI2 | W21: =IF(COUNTA(S21), VLOOKUP(S21, $C$3:$G$18, 4, 0), 0) -> -0.01 | X21: =IF(COUNTA(S21), VLOOKUP(S21, $C$3:$G$18, 5, 0), 0) -> -1.37 | Y21: =W21+Y20 -> 4.02 | Z21: =X21+Z20 -> 38.41
J22: X20AI8321 | K22: =IF(COUNTA(J22), VLOOKUP(J22, $C$3:$G$18, 2, 0), 0) -> 12.5 | L22: =IF(COUNTA(J22), VLOOKUP(J22, $C$3:$G$18, 3, 0), 0) -> AI | M22: 1AI3 | N22: =IF(COUNTA(J22), VLOOKUP(J22, $C$3:$G$18, 4, 0), 0) -> -0.01 | O22: =IF(COUNTA(J22), VLOOKUP(J22, $C$3:$G$18, 5, 0), 0) -> -1.37 | P22: =N22+P21 -> 4.03 | Q22: =O22+Q21 -> 39.71 | S22: X20AI8321 | T22: =IF(COUNTA(S22), VLOOKUP(S22, $C$3:$E$18, 2, 0), 0) -> 12.5 | U22: =IF(COUNTA(S22), VLOOKUP(S22, $C$3:$E$18, 3, 0), 0) -> AI | V22: 3AI3 | W22: =IF(COUNTA(S22), VLOOKUP(S22, $C$3:$G$18, 4, 0), 0) -> -0.01 | X22: =IF(COUNTA(S22), VLOOKUP(S22, $C$3:$G$18, 5, 0), 0) -> -1.37 | Y22: =W22+Y21 -> 4.01 | Z22: =X22+Z21 -> 37.04
J23: X20AI8321 | K23: =IF(COUNTA(J23), VLOOKUP(J23, $C$3:$G$18, 2, 0), 0) -> 12.5 | L23: =IF(COUNTA(J23), VLOOKUP(J23, $C$3:$G$18, 3, 0), 0) -> AI | M23: 1AO1 | N23: =IF(COUNTA(J23), VLOOKUP(J23, $C$3:$G$18, 4, 0), 0) -> -0.01 | O23: =IF(COUNTA(J23), VLOOKUP(J23, $C$3:$G$18, 5, 0), 0) -> -1.37 | P23: =N23+P22 -> 4.02 | Q23: =O23+Q22 -> 38.34 | S23: X20AO4622 | T23: =IF(COUNTA(S23), VLOOKUP(S23, $C$3:$E$18, 2, 0), 0) -> 12.5 | U23: =IF(COUNTA(S23), VLOOKUP(S23, $C$3:$E$18, 3, 0), 0) -> AO | V23: 3AO1 | W23: =IF(COUNTA(S23), VLOOKUP(S23, $C$3:$G$18, 4, 0), 0) -> -0.01 | X23: =IF(COUNTA(S23), VLOOKUP(S23, $C$3:$G$18, 5, 0), 0) -> -1.8 | Y23: =W23+Y22 -> 4 | Z23: =X23+Z22 -> 35.24
J24: X20AO4622 | K24: =IF(COUNTA(J24), VLOOKUP(J24, $C$3:$G$18, 2, 0), 0) -> 12.5 | L24: =IF(COUNTA(J24), VLOOKUP(J24, $C$3:$G$18, 3, 0), 0) -> AO | N24: =IF(COUNTA(J24), VLOOKUP(J24, $C$3:$G$18, 4, 0), 0) -> -0.01 | O24: =IF(COUNTA(J24), VLOOKUP(J24, $C$3:$G$18, 5, 0), 0) -> -1.8 | P24: =N24+P23 -> 4.01 | Q24: =O24+Q23 -> 36.54 | S24: X20PS9400 | T24: =IF(COUNTA(S24), VLOOKUP(S24, $C$3:$E$18, 2, 0), 0) -> 12.5 | U24: =IF(COUNTA(S24), VLOOKUP(S24, $C$3:$E$18, 3, 0), 0) -> Power | V24: PS3 | W24: =IF(COUNTA(S24), VLOOKUP(S24, $C$3:$G$18, 4, 0), 0) -> 7 | X24: =IF(COUNTA(S24), VLOOKUP(S24, $C$3:$G$18, 5, 0), 0) -> 240 | Y24: =W24+Y23 -> 11 | Z24: =X24+Z23 -> 275.24
K25: =IF(COUNTA(J25), VLOOKUP(J25, $C$3:$G$18, 2, 0), 0) -> 0 | L25: =IF(COUNTA(J25), VLOOKUP(J25, $C$3:$G$18, 3, 0), 0) -> 0 | N25: =IF(COUNTA(J25), VLOOKUP(J25, $C$3:$G$18, 4, 0), 0) -> 0 | O25: =IF(COUNTA(J25), VLOOKUP(J25, $C$3:$G$18, 5, 0), 0) -> 0 | P25: =N25+P24 -> 4.01 | Q25: =O25+Q24 -> 36.54 | S25: X20DIF371 | T25: =IF(COUNTA(S25), VLOOKUP(S25, $C$3:$E$18, 2, 0), 0) -> 12.5 | U25: =IF(COUNTA(S25), VLOOKUP(S25, $C$3:$E$18, 3, 0), 0) -> DI | V25: 4DI1 | W25: =IF(COUNTA(S25), VLOOKUP(S25, $C$3:$G$18, 4, 0), 0) -> -0.18 | X25: =IF(COUNTA(S25), VLOOKUP(S25, $C$3:$G$18, 5, 0), 0) -> -1.47 | Y25: =W25+Y24 -> 10.82 | Z25: =X25+Z24 -> 273.77
J26: IE-SW-BLB-08-8TX | K26: =IF(COUNTA(J26), VLOOKUP(J26, $C$3:$G$18, 2, 0), 0) -> 44 | L26: =IF(COUNTA(J26), VLOOKUP(J26, $C$3:$G$18, 3, 0), 0) -> 0 | N26: =IF(COUNTA(J26), VLOOKUP(J26, $C$3:$G$18, 4, 0), 0) -> 0 | O26: =IF(COUNTA(J26), VLOOKUP(J26, $C$3:$G$18, 5, 0), 0) -> 0 | P26: =N26+P25 -> 4.01 | Q26: =O26+Q25 -> 36.54 | S26: X20DOF322 | T26: =IF(COUNTA(S26), VLOOKUP(S26, $C$3:$E$18, 2, 0), 0) -> 12.5 | U26: =IF(COUNTA(S26), VLOOKUP(S26, $C$3:$E$18, 3, 0), 0) -> DO | V26: 4DO1 | W26: =IF(COUNTA(S26), VLOOKUP(S26, $C$3:$G$18, 4, 0), 0) -> -0.28 | X26: =IF(COUNTA(S26), VLOOKUP(S26, $C$3:$G$18, 5, 0), 0) -> -95 | Y26: =W26+Y25 -> 10.54 | Z26: =X26+Z25 -> 178.77
K27: =IF(COUNTA(J27), VLOOKUP(J27, $C$3:$G$18, 2, 0), 0) -> 0 | L27: =IF(COUNTA(J27), VLOOKUP(J27, $C$3:$G$18, 3, 0), 0) -> 0 | N27: =IF(COUNTA(J27), VLOOKUP(J27, $C$3:$G$18, 4, 0), 0) -> 0 | O27: =IF(COUNTA(J27), VLOOKUP(J27, $C$3:$G$18, 5, 0), 0) -> 0 | P27: =N27+P26 -> 4.01 | Q27: =O27+Q26 -> 36.54 | S27: X20AI8321 | T27: =IF(COUNTA(S27), VLOOKUP(S27, $C$3:$E$18, 2, 0), 0) -> 12.5 | U27: =IF(COUNTA(S27), VLOOKUP(S27, $C$3:$E$18, 3, 0), 0) -> AI | V27: 4AI1 | W27: =IF(COUNTA(S27), VLOOKUP(S27, $C$3:$G$18, 4, 0), 0) -> -0.01 | X27: =IF(COUNTA(S27), VLOOKUP(S27, $C$3:$G$18, 5, 0), 0) -> -1.37 | Y27: =W27+Y26 -> 10.53 | Z27: =X27+Z26 -> 177.4
K28: =IF(COUNTA(J28), VLOOKUP(J28, $C$3:$G$18, 2, 0), 0) -> 0 | L28: =IF(COUNTA(J28), VLOOKUP(J28, $C$3:$G$18, 3, 0), 0) -> 0 | N28: =IF(COUNTA(J28), VLOOKUP(J28, $C$3:$G$18, 4, 0), 0) -> 0 | O28: =IF(COUNTA(J28), VLOOKUP(J28, $C$3:$G$18, 5, 0), 0) -> 0 | P28: =N28+P27 -> 4.01 | Q28: =O28+Q27 -> 36.54 | S28: X20AI8321 | T28: =IF(COUNTA(S28), VLOOKUP(S28, $C$3:$E$18, 2, 0), 0) -> 12.5 | U28: =IF(COUNTA(S28), VLOOKUP(S28, $C$3:$E$18, 3, 0), 0) -> AI | V28: 4AI2 | W28: =IF(COUNTA(S28), VLOOKUP(S28, $C$3:$G$18, 4, 0), 0) -> -0.01 | X28: =IF(COUNTA(S28), VLOOKUP(S28, $C$3:$G$18, 5, 0), 0) -> -1.37 | Y28: =W28+Y27 -> 10.52 | Z28: =X28+Z27 -> 176.03
K29: =IF(COUNTA(J29), VLOOKUP(J29, $C$3:$G$18, 2, 0), 0) -> 0 | L29: =IF(COUNTA(J29), VLOOKUP(J29, $C$3:$G$18, 3, 0), 0) -> 0 | N29: =IF(COUNTA(J29), VLOOKUP(J29, $C$3:$G$18, 4, 0), 0) -> 0 | O29: =IF(COUNTA(J29), VLOOKUP(J29, $C$3:$G$18, 5, 0), 0) -> 0 | P29: =N29+P28 -> 4.01 | Q29: =O29+Q28 -> 36.54 | S29: X20AI8321 | T29: =IF(COUNTA(S29), VLOOKUP(S29, $C$3:$E$18, 2, 0), 0) -> 12.5 | U29: =IF(COUNTA(S29), VLOOKUP(S29, $C$3:$E$18, 3, 0), 0) -> AI | V29: 4AI3 | W29: =IF(COUNTA(S29), VLOOKUP(S29, $C$3:$G$18, 4, 0), 0) -> -0.01 | X29: =IF(COUNTA(S29), VLOOKUP(S29, $C$3:$G$18, 5, 0), 0) -> -1.37 | Y29: =W29+Y28 -> 10.51 | Z29: =X29+Z28 -> 174.66
K30: =IF(COUNTA(J30), VLOOKUP(J30, $C$3:$G$18, 2, 0), 0) -> 0 | L30: =IF(COUNTA(J30), VLOOKUP(J30, $C$3:$G$18, 3, 0), 0) -> 0 | N30: =IF(COUNTA(J30), VLOOKUP(J30, $C$3:$G$18, 4, 0), 0) -> 0 | O30: =IF(COUNTA(J30), VLOOKUP(J30, $C$3:$G$18, 5, 0), 0) -> 0 | P30: =N30+P29 -> 4.01 | Q30: =O30+Q29 -> 36.54 | S30: X20AO4622 | T30: =IF(COUNTA(S30), VLOOKUP(S30, $C$3:$E$18, 2, 0), 0) -> 12.5 | U30: =IF(COUNTA(S30), VLOOKUP(S30, $C$3:$E$18, 3, 0), 0) -> AO | V30: 4AO1 | W30: =IF(COUNTA(S30), VLOOKUP(S30, $C$3:$G$18, 4, 0), 0) -> -0.01 | X30: =IF(COUNTA(S30), VLOOKUP(S30, $C$3:$G$18, 5, 0), 0) -> -1.8 | Y30: =W30+Y29 -> 10.5 | Z30: =X30+Z29 -> 172.86
S31: X20DIF371 | T31: =IF(COUNTA(S31), VLOOKUP(S31, $C$3:$E$18, 2, 0), 0) -> 12.5 | U31: =IF(COUNTA(S31), VLOOKUP(S31, $C$3:$E$18, 3, 0), 0) -> DI | V31: 5DI1 | W31: =IF(COUNTA(S31), VLOOKUP(S31, $C$3:$G$18, 4, 0), 0) -> -0.18 | X31: =IF(COUNTA(S31), VLOOKUP(S31, $C$3:$G$18, 5, 0), 0) -> -1.47 | Y31: =W31+Y30 -> 10.32 | Z31: =X31+Z30 -> 171.39
S32: X20DOF322 | T32: =IF(COUNTA(S32), VLOOKUP(S32, $C$3:$E$18, 2, 0), 0) -> 12.5 | U32: =IF(COUNTA(S32), VLOOKUP(S32, $C$3:$E$18, 3, 0), 0) -> DO | V32: 5DO1 | W32: =IF(COUNTA(S32), VLOOKUP(S32, $C$3:$G$18, 4, 0), 0) -> -0.28 | X32: =IF(COUNTA(S32), VLOOKUP(S32, $C$3:$G$18, 5, 0), 0) -> -95 | Y32: =W32+Y31 -> 10.04 | Z32: =X32+Z31 -> 76.39
S33: X20AI8321 | T33: =IF(COUNTA(S33), VLOOKUP(S33, $C$3:$E$18, 2, 0), 0) -> 12.5 | U33: =IF(COUNTA(S33), VLOOKUP(S33, $C$3:$E$18, 3, 0), 0) -> AI | V33: 5AI1 | W33: =IF(COUNTA(S33), VLOOKUP(S33, $C$3:$G$18, 4, 0), 0) -> -0.01 | X33: =IF(COUNTA(S33), VLOOKUP(S33, $C$3:$G$18, 5, 0), 0) -> -1.37 | Y33: =W33+Y32 -> 10.03 | Z33: =X33+Z32 -> 75.02
S34: X20AI8321 | T34: =IF(COUNTA(S34), VLOOKUP(S34, $C$3:$E$18, 2, 0), 0) -> 12.5 | U34: =IF(COUNTA(S34), VLOOKUP(S34, $C$3:$E$18, 3, 0), 0) -> AI | V34: 5AI2 | W34: =IF(COUNTA(S34), VLOOKUP(S34, $C$3:$G$18, 4, 0), 0) -> -0.01 | X34: =IF(COUNTA(S34), VLOOKUP(S34, $C$3:$G$18, 5, 0), 0) -> -1.37 | Y34: =W34+Y33 -> 10.02 | Z34: =X34+Z33 -> 73.65
S35: X20AI8321 | T35: =IF(COUNTA(S35), VLOOKUP(S35, $C$3:$E$18, 2, 0), 0) -> 12.5 | U35: =IF(COUNTA(S35), VLOOKUP(S35, $C$3:$E$18, 3, 0), 0) -> AI | V35: 5AI3 | W35: =IF(COUNTA(S35), VLOOKUP(S35, $C$3:$G$18, 4, 0), 0) -> -0.01 | X35: =IF(COUNTA(S35), VLOOKUP(S35, $C$3:$G$18, 5, 0), 0) -> -1.37 | Y35: =W35+Y34 -> 10.01 | Z35: =X35+Z34 -> 72.28
S36: X20AO4622 | T36: =IF(COUNTA(S36), VLOOKUP(S36, $C$3:$E$18, 2, 0), 0) -> 12.5 | U36: =IF(COUNTA(S36), VLOOKUP(S36, $C$3:$E$18, 3, 0), 0) -> AO | V36: 5AO1 | W36: =IF(COUNTA(S36), VLOOKUP(S36, $C$3:$G$18, 4, 0), 0) -> -0.01 | X36: =IF(COUNTA(S36), VLOOKUP(S36, $C$3:$G$18, 5, 0), 0) -> -1.8 | Y36: =W36+Y35 -> 10 | Z36: =X36+Z35 -> 70.48
S37: X20PS9400 | T37: =IF(COUNTA(S37), VLOOKUP(S37, $C$3:$E$18, 2, 0), 0) -> 12.5 | U37: =IF(COUNTA(S37), VLOOKUP(S37, $C$3:$E$18, 3, 0), 0) -> Power | V37: PS4 | W37: =IF(COUNTA(S37), VLOOKUP(S37, $C$3:$G$18, 4, 0), 0) -> 7 | X37: =IF(COUNTA(S37), VLOOKUP(S37, $C$3:$G$18, 5, 0), 0) -> 240 | Y37: =W37+Y36 -> 17 | Z37: =X37+Z36 -> 310.48
S38: X20DIF371 | T38: =IF(COUNTA(S38), VLOOKUP(S38, $C$3:$E$18, 2, 0), 0) -> 12.5 | U38: =IF(COUNTA(S38), VLOOKUP(S38, $C$3:$E$18, 3, 0), 0) -> DI | V38: 6DI1 | W38: =IF(COUNTA(S38), VLOOKUP(S38, $C$3:$G$18, 4, 0), 0) -> -0.18 | X38: =IF(COUNTA(S38), VLOOKUP(S38, $C$3:$G$18, 5, 0), 0) -> -1.47 | Y38: =W38+Y37 -> 16.82 | Z38: =X38+Z37 -> 309.01
S39: X20DOF322 | T39: =IF(COUNTA(S39), VLOOKUP(S39, $C$3:$E$18, 2, 0), 0) -> 12.5 | U39: =IF(COUNTA(S39), VLOOKUP(S39, $C$3:$E$18, 3, 0), 0) -> DO | V39: 6DO1 | W39: =IF(COUNTA(S39), VLOOKUP(S39, $C$3:$G$18, 4, 0), 0) -> -0.28 | X39: =IF(COUNTA(S39), VLOOKUP(S39, $C$3:$G$18, 5, 0), 0) -> -95 | Y39: =W39+Y38 -> 16.54 | Z39: =X39+Z38 -> 214.01
S40: X20AI8321 | T40: =IF(COUNTA(S40), VLOOKUP(S40, $C$3:$E$18, 2, 0), 0) -> 12.5 | U40: =IF(COUNTA(S40), VLOOKUP(S40, $C$3:$E$18, 3, 0), 0) -> AI | V40: 6AI1 | W40: =IF(COUNTA(S40), VLOOKUP(S40, $C$3:$G$18, 4, 0), 0) -> -0.01 | X40: =IF(COUNTA(S40), VLOOKUP(S40, $C$3:$G$18, 5, 0), 0) -> -1.37 | Y40: =W40+Y39 -> 16.53 | Z40: =X40+Z39 -> 212.64
...

Sheet Common module
A1: Module | B1: CH | C1: P_terminal | D1: M_terminal | E1: TagNo | F1: IOType | G1: SignalType | H1: PSType | I1: SystemUnit | J1: CAT4VName | K1: Description | L1: Min | M1: Max | N1: Unit | O1: Al_LLT | P1: Al_LLD | Q1: Al_LOT | R1: Al_LOD | S1: Al_HOT | T1: AL_HOD | U1: Al_HHT | V1: Al_HHD | W1: ConnectionPoint | X1: Remark | Y1: CAT3
A2: string | B2: double | C2: double | D2: double | E2: string | F2: categorical | G2: categorical | H2: categorical | I2: categorical | J2: string | K2: string | L2: double | M2: double | N2: string | O2: string | P2: double | Q2: string | R2: double | S2: string | T2: double | U2: string | V2: double | W2: string | X2: string | Y2: categorical
A3: No. | B3: CH | C3: (+) | D3: (-) | E3: Tag No. | F3: Signal type | I3: System Unit | J3: Variable name | K3: Description | L3: Range | O3: Alarm | W3: Connection point | X3: Remark
L4: Min | M4: Max | N4: Unit | O4: Low-Low | P4: Delay | Q4: Low | R4: Delay | S4: High | T4: Delay | U4: High-High | V4: Delay
A5: 1CDI1 | B5: 1 | C5: 11 | E5: MOC00-200 | F5: DI | G5: N/O | H5: DC24V | I5: MOCS | J5: CDI1Reserved1 | K5: MOCS F.O Supply pump Auto mode (Reserved) - 미적용 | W5: Front door → IO module | X5: 1=Auto | Y5: FODS
A6: 1CDI1 | B6: 2 | C6: 21 | E6: MOC00-370 | F6: DI | G6: N/O | H6: DC24V | I6: MOCS | J6: AlarmReset | K6: Alarm Reset | W6: Front door → IO module | X6: 1=Reset | Y6: MOCS
A7: 1CDI1 | B7: 3 | C7: 12 | E7: ENG10-700 | F7: DI | G7: N/C | H7: DC24V | I7: MOCS | J7: LowSulfFOSupd | K7: Low Sulfur fuel supplied (S=0.1%) | Q7: 0 | R7: 1 | W7: Yard → MOCS control unit | X7: 1=0.1% Sulfur | Y7: MOCS
A8: 1CDI1 | B8: 4 | C8: 22 | E8: MOC00-803 | F8: DI | G8: N/C | H8: DC24V | I8: MOCS | J8: InternalPwrFail | K8: Internal power Fail | Q8: 0 | R8: 1 | W8: Internal → IO module | X8: 0=Fail | Y8: MOCS
A9: 1CDI1 | B9: 5 | C9: 13 | E9: MOC00-804 | F9: DI | G9: N/C | H9: DC24V | I9: MOCS | J9: ExternalPwrFail | K9: External power Fail | Q9: 0 | R9: 1 | W9: Internal → IO module | X9: 0=Fail | Y9: MOCS
A10: 1CDI1 | B10: 6 | C10: 23 | E10: MOC00-805 | F10: DI | G10: N/C | H10: DC24V | I10: MOCS | J10: FanPwrFail | K10: Fan power Fail | Q10: 0 | R10: 1 | W10: Internal → IO module | X10: 0=Fail | Y10: MOCS
A11: 1CDI1 | B11: 7 | C11: 14 | E11: MOC00-806 | F11: DI | G11: N/C | H11: DC24V | I11: MOCS | J11: ESDcircuitPwrFail | K11: ESD circuit power Fail | Q11: 0 | R11: 1 | W11: Internal → IO module | X11: 0=Fail | Y11: MOCS
A12: 1CDI1 | B12: 8 | C12: 24 | E12: MOC00-807 | F12: DI | G12: N/C | H12: DC24V | I12: MOCS | J12: UPSPwrFail | K12: UPS power Fail | Q12: 0 | R12: 1 | W12: Internal → IO module | X12: 0=Fail | Y12: MOCS
A13: 1CDI1 | B13: 9 | C13: 15 | E13: FSP00-201 | F13: DI | G13: N/O | H13: DC24V | I13: FODS | J13: No1FOSPumpRemote | K13: No.1 MOCS F.O Supply pump Remote | Q13: 0 | R13: 1 | W13: No.1 MOCS F.O. Supply pump starter → MOCS control unit | X13: 1=Remote | Y13: FODS
A14: 1CDI1 | B14: 10 | C14: 25 | E14: FSP00-301 | F14: DI | G14: N/C | H14: DC24V | I14: FODS | J14: No1FOSPumpAbnormal | K14: No.1 MOCS F.O Supply pump Abnormal | Q14: 0 | R14: 1 | W14: No.1 MOCS F.O. Supply pump starter → MOCS control unit | X14: 0=Abnormal | Y14: FODS
A15: 1CDI1 | B15: 11 | C15: 16 | E15: FSP00-221 | F15: DI | G15: N/O | H15: DC24V | I15: FODS | J15: No1FOSPumpRunning | K15: No.1 MOCS F.O Supply pump Running | Q15: 0 | R15: 10 | W15: No.1 MOCS F.O. Supply pump starter → MOCS control unit | X15: 1=Running | Y15: FODS
A16: 1CDI1 | B16: 12 | C16: 26 | E16: FSP00-202 | F16: DI | G16: N/O | H16: DC24V | I16: FODS | J16: No2FOSPumpRemote | K16: No.2 MOCS F.O Supply pump Remote | Q16: 0 | R16: 1 | W16: No.2 MOCS F.O. Supply pump starter → MOCS control unit | X16: 1=Remote | Y16: FODS
A17: 1CDI1 | B17: 13 | C17: 17 | E17: FSP00-302 | F17: DI | G17: N/C | H17: DC24V | I17: FODS | J17: No2FOSPumpAbnormal | K17: No.2 MOCS F.O Supply pump Abnormal | Q17: 0 | R17: 1 | W17: No.2 MOCS F.O. Supply pump starter → MOCS control unit | X17: 0=Abnormal | Y17: FODS
A18: 1CDI1 | B18: 14 | C18: 27 | E18: FSP00-222 | F18: DI | G18: N/O | H18: DC24V | I18: FODS | J18: No2FOSPumpRunning | K18: No.2 MOCS F.O Supply pump Running | Q18: 0 | R18: 10 | W18: No.2 MOCS F.O. Supply pump starter → MOCS control unit | X18: 1=Running | Y18: FODS
A19: 1CDI1 | B19: 15 | C19: 18 | E19: FSU10-200 | F19: DI | G19: N/O | H19: DC24V | I19: FODS | J19: FOSPumpRunningYard | K19: MOCS F.O Supply pump Running from Yard | Q19: 0 | R19: 10 | W19: Yard → MOCS control unit | X19: 1=Running
A20: 1CDI1 | B20: 16 | C20: 28 | J20: CDI1Reserved16
A21: 1CDO1 | B21: 1 | C21: 11 | E21: MOCS11-331 | F21: DO | G21: N/C | H21: Isolated | I21: MOCS | J21: MOCSCmmnAlarm | K21: MOCS Common Alarm | W21: MOCS control unit → Yard | X21: 0=Alarm | Y21: MOCS
A22: 1CDO1 | B22: 2 | C22: 21 | E22: MOC01-381 | F22: DO | G22: N/O | I22: MOCS | J22: MOCSCmmnAlarmLamp | K22: MOCS Common Alarm Lamp | W22: MOCS control unit → Front door | X22: 1=Lamp on | Y22: MOCS
A23: 1CDO1 | B23: 3 | C23: 12 | E23: MOC01-390 | F23: DO | G23: N/O | I23: MOCS | J23: MOCSCmmnAlarmBuzzer | K23: MOCS Common Alarm Buzzer | W23: MOCS control unit → Front door | X23: 1=Buzzer on | Y23: MOCS
A24: 1CDO1 | B24: 4 | C24: 22 | E24: FSP01-111 | F24: DO | G24: N/O | H24: Isolated | I24: MOCS | J24: No1FOSPumpRunCmd | K24: No.1 MOCS F.O Supply pump Run Command | W24: MOCS control unit → No.1 MOCS F.O. Supply pump starter | X24: 1=Run | Y24: FODS
A25: 1CDO1 | B25: 5 | C25: 13 | E25: FSP01-112 | F25: DO | G25: N/O | H25: Isolated | I25: FODS | J25: No2FOSPumpRunCmd | K25: No.2 MOCS F.O Supply pump Run Command | W25: MOCS control unit → No.2 MOCS F.O. Supply pump starter | X25: 1=Run | Y25: FODS
A26: 1CDO1 | B26: 6 | C26: 23 | E26: FSU11-110 | F26: DO | G26: N/O | H26: Isolated | I26: FODS | J26: FOSPumpRunRqstYard | K26: MOCS F.O Supply pump Run Request to Yard | W26: MOCS control unit → Yard | X26: 1=Run | Y26: FODS
A27: 1CDO1 | B27: 7 | C27: 14 | E27: FSU11-300 | F27: DO | G27: N/C | H27: Isolated | I27: FODS | J27: FOSPumpFailYard | K27: MOCS F.O Supply pump Fail to Yard | W27: MOCS control unit → Yard | X27: 0=Fail | Y27: FODS
A28: 1CDO1 | B28: 8 | C28: 24 | J28: CDO1Reserved8
A29: 1CDO1 | B29: 9 | C29: 15 | J29: CDO1Reserved9
A30: 1CDO1 | B30: 10 | C30: 25 | J30: CDO1Reserved10
A31: 1CDO1 | B31: 11 | C31: 16 | J31: CDO1Reserved11
A32: 1CDO1 | B32: 12 | C32: 26 | J32: CDO1Reserved12
A33: 1CDO1 | B33: 13 | C33: 17 | J33: CDO1Reserved13
A34: 1CDO1 | B34: 14 | C34: 27 | J34: CDO1Reserved14
A35: 1CDO1 | B35: 15 | C35: 18 | J35: CDO1Reserved15
A36: 1CDO1 | B36: 16 | C36: 28 | J36: CDO1Reserved16
A37: 1CAI1 | B37: 1 | C37: 11 | D37: 21 | E37: PT102040 | F37: AI | G37: 4-20mA | H37: DC24V | I37: FODS | J37: FOSupInletPress | K37: MOCS F.O Supply Inlet Press | L37: -1 | M37: 10 | N37: bar | Q37: -0.2 | R37: 2 | W37: MOCS F.O. Supply unit → MOCS control unit | Y37: FODS
A38: 1CAI1 | B38: 2 | C38: 12 | D38: 22 | E38: PT102041 | F38: AI | G38: 4-20mA | H38: DC24V | I38: FODS | J38: FOSupOutletPress | K38: MOCS F.O Supply Outlet Press | L38: 0 | M38: 16 | N38: bar | O38: 4 | P38: 5 | Q38: 5 | R38: 5 | S38: 11 | T38: 10 | U38: 12 | V38: 10 | W38: MOCS F.O. Supply unit → MOCS control unit | Y38: FODS
A39: 1CAI1 | B39: 3 | C39: 13 | D39: 23 | J39: CAI1Reserved3
A40: 1CAI1 | B40: 4 | C40: 14 | D40: 24 | J40: CAI1Reserved4
...

Sheet No.# Module
A1: Module | B1: CH | C1: P_terminal | D1: M_terminal | E1: TagNo | F1: IOType | G1: SignalType | H1: PSType | I1: SystemUnit | J1: CAT4VName | K1: Description | L1: Min | M1: Max | N1: Unit | O1: Al_LLT | P1: Al_LLD | Q1: Al_LOT | R1: Al_LOD | S1: Al_HOT | T1: AL_HOD | U1: Al_HHT | V1: Al_HHD | W1: ConnectionPoint | X1: Remark
A2: string | B2: double | C2: double | D2: double | E2: string | F2: categorical | G2: categorical | H2: categorical | I2: categorical | J2: string | K2: string | L2: double | M2: double | N2: string | O2: double | P2: double | Q2: double | R2: double | S2: double | T2: double | U2: double | V2: double | W2: string | X2: string
A3: Module | B3: CH | C3: (+) | D3: (-) | E3: Tag No. | F3: Signal type | I3: Unit | J3: Variable name | K3: Description | L3: Range | O3: Alarm | W3: Connection point | X3: Remark
L4: Min | M4: Max | N4: Unit | O4: Low-Low | P4: Delay | Q4: Low | R4: Delay | S4: High | T4: Delay | U4: High-High | V4: Delay
A5: #DI1 | B5: 1 | C5: 11 | E5: ENG10-70# | F5: DI | G5: N/C | H5: DC24V | I5: MOCS | J5: IDI1Reserved1 | K5: No.# G/E Low Sulfur fuel supplied(S=0.1%)(Reserved)-Not applied | Q5: 0 | R5: 1 | W5: Yard → MOCS control unit | X5: 1=0.1% Sulfur
A6: #DI1 | B6: 2 | C6: 21 | E6: MOC00-20# | F6: DI | G6: N/O | H6: DC24V | I6: MOCS | J6: MOCSRemote | K6: No.# MOCS Remote/Local | W6: Front door → MOCS control unit | X6: 1=Remote
A7: #DI1 | B7: 3 | C7: 12 | E7: MOC00-91#P | F7: DI | G7: N/C | H7: DC24V | I7: MOCS | J7: MOCSEmcyStopPanel | K7: No.# MOCS Em'cy stop From panel(To module) | Q7: 0 | R7: 0.1 | W7: Internal relay → IO module | X7: 0=Em'cy Stop
A8: #DI1 | B8: 4 | C8: 22 | E8: MOC00-91#E | F8: DI | G8: N/C | H8: DC24V | I8: MOCS | J8: MOCSEmcystopECR | K8: No.# MOCS Em'cy stop From ECR(To module) | Q8: 0 | R8: 0.1 | W8: Internal relay → IO module | X8: 0=Em'cy Stop
A9: #DI1 | B9: 5 | C9: 13 | E9: MOC00-91#B | F9: DI | G9: N/C | H9: DC24V | I9: MOCS | J9: MOCSEmcystopBridge | K9: No.# MOCS Em'cy stop From Bridge(To module) | Q9: 0 | R9: 0.1 | W9: Internal relay → IO module | X9: 0=Em'cy Stop
A10: #DI1 | B10: 6 | C10: 23 | E10: MOC10-11# | F10: DI | G10: N/O | H10: DC24V | I10: MOCS | J10: MOCSStart | K10: No.# MOCS Start | W10: Yard → MOCS control unit | X10: 1=Start
A11: #DI1 | B11: 7 | C11: 14 | E11: MBV10-11# | F11: DI | G11: N/O | H11: DC24V | I11: MOCS | J11: MOCSPreparation | K11: No.# MOCS Preparation | W11: Yard → MOCS control unit | X11: 1=Preparation
A12: #DI1 | B12: 8 | C12: 24 | E12: MOC10-01# | F12: DI | G12: N/O | H12: DC24V | I12: MOCS | J12: MOCSStop | K12: No.# MOCS Stop | W12: Yard → MOCS control unit | X12: 1=Stop
A13: #DI1 | B13: 9 | C13: 15 | E13: XC104#01-2 | F13: DI | G13: N/O | H13: DC24V | I13: MOCS | J13: RSVFeedOpen | K13: No.# MOCS RSV Feedback(Open) | W13: RSV → MOCS control unit | X13: 1=Open
A14: #DI1 | B14: 10 | C14: 25 | E14: XC104#01-3 | F14: DI | G14: N/O | H14: DC24V | I14: MOCS | J14: RSVFeedClosed | K14: No.# MOCS RSV Feedback(Closed) | W14: RSV → MOCS control unit | X14: 1=Close
A15: #DI1 | B15: 11 | C15: 16 | E15: XC104#02-2 | F15: DI | G15: N/O | H15: DC24V | I15: MOCS | J15: RBVFeedOpen | K15: No.# MOCS RBV Feedback(Open) | W15: RBV → MOCS control unit | X15: 1=Open
A16: #DI1 | B16: 12 | C16: 26 | E16: XC104#02-3 | F16: DI | G16: N/O | H16: DC24V | I16: MOCS | J16: RBVFeedClosed | K16: No.# MOCS RBV Feedback(Closed) | W16: RBV → MOCS control unitt | X16: 1=Close
A17: #DI1 | B17: 13 | C17: 17 | E17: TS103#42 | F17: DI | G17: N/C | H17: DC24V | I17: FODS | J17: FODosFOInletTemp | K17: No.# MOCS F.O Dosing Fuel Oil Inlet Temp | Q17: 0 | R17: 1 | W17: MOCS F.O. Dosing unit → MOCS control unit | X17: 0 = 60℃ 이상
A18: #DI1 | B18: 14 | C18: 27 | E18: XC104#04-2 | F18: DI | G18: N/O | H18: DC24V | I18: SCR | J18: IDI1Reserved14 | K18: No.# SCR Inlet Valve Feedback(Open)(Reserved)-Not applied | W18: SCR Inlet Valve → MOCS control unit | X18: 1=Open
A19: #DI1 | B19: 15 | C19: 18 | E19: XC104#04-3 | F19: DI | G19: N/O | H19: DC24V | I19: SCR | J19: IDI1Reserved15 | K19: No.# SCR Inlet Valve Feedback(Closed)(Reserved)-Not applied | W19: SCR Inlet Valve → MOCS control unit | X19: 1=Close
A20: #DI1 | B20: 16 | C20: 28 | I20: SCR | J20: SCRFlushRun | K20: No.# SCR Flush Run(Draft) | W20: SCR control unit → MOCS control unit
A21: #DO1 | B21: 1 | C21: 11 | E21: MOC11-20# | F21: DO | G21: N/O | H21: Isolated | I21: MOCS | J21: MOCSReady | K21: No.# MOCS Ready | W21: MOCS control unit → Yard | X21: 1=Ready
A22: #DO1 | B22: 2 | C22: 21 | E22: MBV11-22# | F22: DO | G22: N/O | H22: Isolated | I22: MOCS | J22: AllFlowThroughMOCS | K22: No.# All Flow Through MOCS | W22: MOCS control unit → Yard | X22: 1=All
A23: #DO1 | B23: 3 | C23: 12 | E23: MOC11-22# | F23: DO | G23: N/O | H23: Isolated | I23: MOCS | J23: MOCSActive | K23: No.# MOCS Active | W23: MOCS control unit → Yard | X23: 1=Active
A24: #DO1 | B24: 4 | C24: 22 | E24: MOC11-50# | F24: DO | G24: N/O | H24: Isolated | I24: FODS | J24: FODSFlushRun | K24: No.# MOCS F.O Dosing system Flush Run | W24: MOCS control unit → Yard | X24: 1=Flush
A25: #DO1 | B25: 5 | C25: 13 | E25: ZV103#01 | F25: DO | G25: N/O | H25: DC24V | I25: FODS | J25: FODosAtomAirSolVV | K25: No.# MOCS F.O Dosing Atomizing Air Sol. VV | W25: MOCS control unit → MOCS F.O. Dosing unit | X25: 1=Open
A26: #DO1 | B26: 6 | C26: 23 | E26: ZV103#02 | F26: DO | G26: N/O | H26: DC24V | I26: FODS | J26: FODosPurgingAirSolVv | K26: No.# MOCS F.O Dosing Purging Air Sol. VV | W26: MOCS control unit → MOCS F.O. Dosing unit | X26: 1=Open
A27: #DO1 | B27: 7 | C27: 14 | E27: ZV103#03 | F27: DO | G27: N/O | H27: DC24V | I27: FODS | J27: FODosFOInletSolVv | K27: No.# MOCS F.O Dosing Fuel Oil Inlet Sol. VV | W27: MOCS control unit → MOCS F.O. Dosing unit | X27: 1=Open
A28: #DO1 | B28: 8 | C28: 24 | E28: ZV103#04 | F28: DO | G28: N/O | H28: DC24V | I28: FODS | J28: FODosFOOutletSolVv | K28: No.# MOCS F.O Dosing Fuel Oil Outlet Sol. VV | W28: MOCS control unit → MOCS F.O. Dosing unit | X28: 1=Open
A29: #DO1 | B29: 9 | C29: 15 | E29: ZV103#05 | F29: DO | G29: N/O | H29: DC24V | I29: FODS | J29: FODosFOReturnSolVv | K29: No.# MOCS F.O Dosing Fuel Oil Return Sol. VV | W29: MOCS control unit → MOCS F.O. Dosing unit | X29: 1=Open
A30: #DO1 | B30: 10 | C30: 25 | E30: XC104#01-1 | F30: DO | G30: N/C | H30: DC24V | I30: MOCS | J30: MOCSRSVSetpoint | K30: No.# MOCS RSV Setpoint | W30: MOCS control unit → MOCS RSV | X30: 1= Close
A31: #DO1 | B31: 11 | C31: 16 | E31: XC104#02-1 | F31: DO | G31: N/C | H31: DC24V | I31: MOCS | J31: MOCSRBVSetpoint | K31: No.# MOCS RBV Setpoint | W31: MOCS control unit → MOCS RBV | X31: 1= Close
A32: #DO1 | B32: 12 | C32: 26 | E32: ZV105#01 | F32: DO | G32: N/O | H32: DC24V | I32: MOCS | J32: MOCSVentingSealingSolVv | K32: No.# MOCS Venting & Sealing Sol. VV | W32: MOCS control unit → MOCS Venting&Sealing unit | X32: 1=Open
A33: #DO1 | B33: 13 | C33: 17 | E33: XC104#04-1 | F33: DO | G33: N/C | H33: DC24V | I33: SCR | J33: IDO1Reserved13 | K33: No.# SCR Inlet Valve Setpoint(Reserved)-Not applied | W33: MOCS control unit → SCR Inlet Valve | X33: 1= Close
A34: #DO1 | B34: 14 | C34: 27 | I34: SCR | J34: AllFlowThroughSCR | K34: No.# SCR Allowed(Draft) | W34: MOCS control unit → SCR control unit
A35: #DO1 | B35: 15 | C35: 18 | J35: IDO1Reserved15
A36: #DO1 | B36: 16 | C36: 28 | J36: IDO1Reserved16
A37: #AI1 | B37: 1 | C37: 11 | D37: 21 | E37: TC106#40 | F37: AI | G37: 4-20mA | H37: DC24V | I37: MOCS | J37: InjPipInletTemp | K37: No.# MOCS Injection pipe Inlet Temp | L37: 0 | M37: 600 | N37: °C | W37: MOCS Injection pipe Inlet Temp → MOCS control unit
A38: #AI1 | B38: 2 | C38: 12 | D38: 22 | E38: TC107#40 | F38: AI | G38: 4-20mA | H38: DC24V | I38: MOCS | J38: ChmbInletTemp | K38: No.# MOCS Chamber Inlet Temp | L38: 0 | M38: 800 | N38: °C | O38: 280 | P38: 10 | Q38: 290 | R38: 10 | S38: 480 | T38: 10 | U38: 500 | V38: 60 | W38: MOCS Chamber Inlet Temp → MOCS Chamber instrument panel → MOCS control unit
A39: #AI1 | B39: 3 | C39: 13 | D39: 23 | E39: TC107#41 | F39: AI | G39: 4-20mA | H39: DC24V | I39: MOCS | J39: ChmbMiddleTemp | K39: No.# MOCS Chamber Middle Temp | L39: 0 | M39: 800 | N39: °C | O39: 280 | P39: 10 | Q39: 290 | R39: 10 | S39: 500 | T39: 10 | U39: 520 | V39: 1 | W39: MOCS Chamber Middle Temp → MOCS Chamber instrument panel → MOCS control unit
A40: #AI1 | B40: 4 | C40: 14 | D40: 24 | E40: TC107#42 | F40: AI | G40: 4-20mA | H40: DC24V | I40: MOCS | J40: ChmbOutletTemp | K40: No.# MOCS Chamber Outlet Temp | L40: 0 | M40: 800 | N40: °C | O40: 280 | P40: 10 | Q40: 290 | R40: 10 | S40: 580 | T40: 10 | U40: 600 | V40: 1 | W40: MOCS Chamber Outlet Temp → MOCS Chamber instrument panel → MOCS control unit
...

Sheet Terminal_Arr
B2: Terminal | D2: Description | E2: Remark | F2: Connection
B3: 1X1 | D3: Power source | E3: AC220V | F3: From Yard
B4: 1X2 | D4: Common power supply | E4: CPU, Monitor, I/O card
B5: 2X1 | D5: Common internal power supply 1
B6: 2X2 | D6: Common internal power supply 2
B7: 2X3 | D7: Common internal wiring
B8: 1C1 | D8: F.O. Supply unit & starter
B9: 0Y1 | D9: Common yard interface | F9: From yard
B10: 0Y2 | D10: 통신 interface | F10: From yard/engine
B11: 3X# | D11: Em'cy stop
B12: 4X# | D12: No.# MOCS power supply | E12: Sol.VV
B13: 5X# | D13: No.# MOCS internal wiring 1
B14: 6X# | D14: No.# MOCS internal wiring 2
B15: 7X# | D15: No.# MOCS internal wiring 3
B16: 8X# | D16: No.# MOCS internal wiring 4
B17: 1Y# | D17: No.# Yard interface | F17: From yard
B18: 2Y# | D18: No.# F.O. Dosing unit | F18: From yard
B19: 3Y# | D19: No.# RSV | F19: From yard
B20: 4Y# | D20: No.# RBV | F20: From yard
B21: 5Y# | D21: No.# RTV | F21: From yard
B22: 6Y# | D22: No.# Venting&Sealing unit | F22: From yard
B23: 7Y# | D23: No.# Injection pipe & Chamber instrument panel | F23: From yard

Sheet Common TB
B1: Skid | C1: Tag No. | D1: Signal type | F1: Internal power T/B | I1: External T/B | N1: Power T/B | Q1: MCCB | R1: Fuse | S1: Relay | X1: Module | AB1: Description | AC1: Range | AF1: Alarm | AK1: Connection point | AL1: Remark
A2: NO | B2: Skid | C2: Tag No. | D2: Signal type | E2: Signal type | F2: No. | G2: 24V | H2: 0V | I2: No. | J2: 24V | K2: (+) | L2: (-) | M2: 0V | N2: No. | O2: 24V | P2: 0V | S2: No. | T2: Contact | U2: GND | V2: 24V | W2: 0V | X2: No. | Y2: CH | Z2: (+) | AA2: (-) | AB2: Description | AC2: Min. | AD2: Max. | AE2: Unit | AF2: Low-Low | AG2: Low | AH2: High | AI2: High-High | AJ2: Delay | AK2: Connection point | AL2: Remark
B3: Main power | F3: 1X1 | G3: 1 | H3: 2
B4: Monitor power | F4: 1X2 | G4: 1 | H4: 2
B5: Ethernet hub power | F5: 1X2 | G5: 3 | H5: 4
B6: CPU power | F6: 1X2 | G6: 5 | H6: 6
B7: PS2 power | F7: 1X2 | G7: 7 | H7: 8
B8: PS3 power | F8: 1X2 | G8: 9 | H8: 10
B9: PS4 power | F9: 1X2 | G9: 11 | H9: 12
B10: Main power lamp | F10: 1X3 | G10: 1 | H10: 2
B11: Alarm lamp | F11: 1X3 | G11: 3 | H11: 4
B12: Alarm lamp | F12: 1X3 | G12: 5 | H12: 6
B13: Alarm buzzer | F13: 1X3 | G13: 7 | H13: 8
B14: Alarm buzzer | F14: 1X3 | G14: 9 | H14: 10
B15: Lamp test button | F15: 1X3 | G15: 11 | H15: 12
B18: Internal connection | C18: MOC00-200 | D18: DI | E18: N/O | F18: 2X1 | G18: 1 | H18: 2 | X18: 1CDI1 | Y18: 1 | Z18: 11 | AB18: F.O. Supply pump Auto mode | AC18: - | AD18: - | AE18: - | AF18: - | AG18: - | AH18: - | AI18: - | AJ18: - | AK18: Front door → IO module | AL18: 1=Auto
B19: Internal connection | C19: MOC00-370 | D19: DI | E19: N/O | F19: 2X1 | G19: 3 | H19: 4 | X19: 1CDI1 | Y19: 2 | Z19: 21 | AB19: Alarm Reset | AC19: - | AD19: - | AE19: - | AF19: - | AG19: - | AH19: - | AI19: - | AJ19: - | AK19: Front door → IO module | AL19: 1=Reset
B20: Internal connection | C20: MOC01-381 | D20: DO | E20: N/O | F20: 2X1 | G20: 5 | H20: 6 | N20: 2X2 | O20: 29 | P20: 30 | S20: 1KC4 | T20: N/O | U20: GND | V20: A1 | W20: A2 | X20: 1CDO1 | Y20: 2 | Z20: 21 | AB20: MOCS common alarm lamp | AK20: IO module → Front door | AL20: 1=Lamp on
B21: Internal connection | C21: MOC01-390 | D21: DO | E21: N/O | F21: 2X1 | G21: 7 | H21: 8 | N21: 2X2 | O21: 31 | P21: 32 | S21: 1KC5 | T21: N/O | U21: GND | V21: A1 | W21: A2 | X21: 1CDO1 | Y21: 3 | Z21: 12 | AB21: MOCS common alarm buzzer | AC21: - | AD21: - | AE21: - | AF21: - | AG21: - | AH21: - | AI21: - | AJ21: - | AK21: IO module → Front door | AL21: 1=Buzzer on
B22: Internal connection | C22: - | D22: - | E22: N/O | N22: 2X2 | O22: 32 | P22: 33 | S22: 1KC6 | T22: N/O | U22: GND | V22: A1 | W22: A2 | X22: - | Y22: - | Z22: - | AA22: - | AB22: MOCS Lamp&Buzzer test Push button
B23: Internal connection | C23: MOC00-803 | D23: DI | E23: N/C | F23: 2X1 | G23: 9 | H23: 10 | X23: 1CDI1 | Y23: 4 | Z23: 22 | AB23: Internal power Fail | AC23: - | AD23: - | AE23: - | AF23: - | AG23: - | AH23: - | AI23: - | AJ23: - | AK23: Internal relay → IO module | AL23: 0=Fail
B24: Internal connection | C24: MOC00-804 | D24: DI | E24: N/C | F24: 2X1 | G24: 11 | H24: 12 | X24: 1CDI1 | Y24: 5 | Z24: 13 | AB24: External power Fail | AC24: - | AD24: - | AE24: - | AF24: - | AG24: - | AH24: - | AI24: - | AJ24: - | AK24: Internal relay → IO module | AL24: 0=Fail
B25: Internal connection | C25: MOC00-805 | D25: DI | E25: N/C | F25: 2X1 | G25: 13 | H25: 14 | X25: 1CDI1 | Y25: 6 | Z25: 23 | AB25: Fan power Fail | AC25: - | AD25: - | AE25: - | AF25: - | AG25: - | AH25: - | AI25: - | AJ25: - | AK25: Internal relay → IO module | AL25: 0=Fail
B26: Internal connection | C26: MOC00-806 | D26: DI | E26: N/C | F26: 2X1 | G26: 15 | H26: 16 | X26: 1CDI1 | Y26: 7 | Z26: 14 | AB26: ESD circuit power Fail | AC26: - | AD26: - | AE26: - | AF26: - | AG26: - | AH26: - | AI26: - | AJ26: - | AK26: Internal relay → IO module | AL26: 0=Fail
B27: Internal connection | C27: MOC00-807 | D27: DI | E27: N/C | F27: 2X1 | G27: 17 | H27: 18 | X27: 1CDI1 | Y27: 8 | Z27: 24 | AB27: UPS power Fail | AC27: - | AD27: - | AE27: - | AF27: - | AG27: - | AH27: - | AI27: - | AJ27: - | AK27: Internal relay → IO module | AL27: 0=Fail
B28: Yard interface | C28: MOC11-800 | D28: DO | E28: N/C | F28: 1X1 | G28: 1 | H28: 2 | I28: 0Y1 | K28: 1 | L28: 2 | S28: KE1 | T28: N/C | U28: GND | V28: 1X1: 1 | W28: 1X1: 2 | X28: - | Y28: - | Z28: - | AA28: - | AB28: MOCS Main power fail | AC28: - | AD28: - | AE28: - | AF28: - | AG28: - | AH28: - | AI28: - | AJ28: - | AK28: Internal relay → Yard | AL28: 0=Fail
B29: Yard interface | C29: ENG10-700 | D29: DI | E29: N/C | F29: 2X2 | G29: 29 | H29: 30 | I29: 0Y1 | K29: 3 | L29: 4 | X29: 1CDI1 | Y29: 3 | Z29: 12 | AB29: Low Sulfur fuel supplied (S=0.1%) | AC29: - | AD29: - | AE29: - | AF29: - | AG29: - | AH29: - | AI29: - | AJ29: - | AK29: Yard → MOCS control unit | AL29: 1=0.1% Sulfur
B30: Yard interface | C30: MOC11-331 | D30: DO | E30: N/C | F30: 2X2 | G30: 31 | H30: 32 | I30: 0Y1 | K30: 5 | L30: 6 | S30: 1KC3 | T30: N/C | U30: GND | V30: A1 | W30: A2 | X30: 1CDO1 | Y30: 1 | Z30: 11 | AB30: MOCS Common Alarm | AC30: - | AD30: - | AE30: - | AF30: - | AG30: - | AH30: - | AI30: - | AJ30: - | AK30: MOCS control unit → Yard | AL30: 0=Alarm
B31: Yard interface | D31: RS485 | I31: 0Y2 | K31: 1 | L31: 2 | AB31: SCR-AMS Modbus RTU (Serial communication) | AC31: - | AD31: - | AE31: - | AF31: - | AG31: - | AH31: - | AI31: - | AJ31: - | AK31: SCR control unit ↔ Yard
B32: No.1 F.O. Supply pump starter panel | C32: FSP00-201 | D32: DI | E32: N/O | F32: 2X2 | G32: 1 | H32: 2 | I32: 1C1 | J32: 1 | K32: 2 | X32: 1CDI1 | Y32: 9 | Z32: 15 | AB32: No.1 F.O. Supply pump Remote | AC32: - | AD32: - | AE32: - | AF32: - | AG32: - | AH32: - | AI32: - | AJ32: - | AK32: No.1 F.O. Supply pump starter → MOCS control unit | AL32: 1=Remote
B33: No.1 F.O. Supply pump starter panel | C33: FSP00-301 | D33: DI | E33: N/C | F33: 2X2 | G33: 3 | H33: 4 | I33: 1C1 | J33: 3 | K33: 4 | X33: 1CDI1 | Y33: 10 | Z33: 25 | AB33: No.1 F.O. Supply pump Abnormal | AC33: - | AD33: - | AE33: - | AF33: - | AG33: - | AH33: - | AI33: - | AJ33: - | AK33: No.1 F.O. Supply pump starter → MOCS control unit | AL33: 0=Abnormal
B34: No.1 F.O. Supply pump starter panel | C34: FSP00-221 | D34: DI | E34: N/O | F34: 2X2 | G34: 5 | H34: 6 | I34: 1C1 | J34: 5 | K34: 6 | X34: 1CDI1 | Y34: 11 | Z34: 16 | AB34: No.1 F.O. Supply pump Running | AC34: - | AD34: - | AE34: - | AF34: - | AG34: - | AH34: - | AI34: - | AJ34: - | AK34: No.1 F.O. Supply pump starter → MOCS control unit | AL34: 1=Running
B35: No.2 F.O. Supply pump starter panel | C35: FSP00-202 | D35: DI | E35: N/O | F35: 2X2 | G35: 13 | H35: 14 | I35: 1C1 | J35: 11 | K35: 12 | X35: 1CDI1 | Y35: 12 | Z35: 26 | AB35: No.2 F.O. Supply pump Remote | AC35: - | AD35: - | AE35: - | AF35: - | AG35: - | AH35: - | AI35: - | AJ35: - | AK35: No.2 F.O. Supply pump starter → MOCS control unit | AL35: 1=Remote
B36: No.2 F.O. Supply pump starter panel | C36: FSP00-302 | D36: DI | E36: N/C | F36: 2X2 | G36: 15 | H36: 16 | I36: 1C1 | J36: 13 | K36: 14 | X36: 1CDI1 | Y36: 13 | Z36: 17 | AB36: No.2 F.O. Supply pump Abnormal | AC36: - | AD36: - | AE36: - | AF36: - | AG36: - | AH36: - | AI36: - | AJ36: - | AK36: No.2 F.O. Supply pump starter → MOCS control unit | AL36: 0=Abnormal
B37: No.2 F.O. Supply pump starter panel | C37: FSP00-222 | D37: DI | E37: N/O | F37: 2X2 | G37: 17 | H37: 18 | I37: 1C1 | J37: 15 | K37: 16 | X37: 1CDI1 | Y37: 14 | Z37: 27 | AB37: No.2 F.O. Supply pump Running | AC37: - | AD37: - | AE37: - | AF37: - | AG37: - | AH37: - | AI37: - | AJ37: - | AK37: No.2 F.O. Supply pump starter → MOCS control unit | AL37: 1=Running
B38: No.1 F.O. Supply pump starter panel | C38: FSP01-111 | D38: DO | E38: N/O | F38: 2X2 | G38: 7 | H38: 8 | I38: 1C1 | K38: 7 | L38: 8 | S38: 1KC1 | T38: N/O | U38: GND | V38: A1 | W38: A2 | X38: 1CDO1 | Y38: 4 | Z38: 22 | AB38: No.1 F.O. Supply pump Run Command | AC38: - | AD38: - | AE38: - | AF38: - | AG38: - | AH38: - | AI38: - | AJ38: - | AK38: MOCS control unit → No.1 F.O. Supply pump starter | AL38: 1=Run
B39: No.2 F.O. Supply pump starter panel | C39: FSP01-112 | D39: DO | E39: N/O | F39: 2X2 | G39: 19 | H39: 20 | I39: 1C1 | K39: 17 | L39: 18 | S39: 1KC2 | T39: N/O | U39: GND | V39: A1 | W39: A2 | X39: 1CDO1 | Y39: 5 | Z39: 13 | AB39: No.2 F.O. Supply pump Run Command | AC39: - | AD39: - | AE39: - | AF39: - | AG39: - | AH39: - | AI39: - | AJ39: - | AK39: MOCS control unit → No.2 F.O. Supply pump starter | AL39: 1=Run
B40: F.O. Supply unit | C40: PT102040 | D40: AI | E40: 4-20mA | F40: 2X2 | G40: 25 | H40: 26 | I40: 1C1 | J40: 21 | K40: 22 | R40: FS1 | X40: 1CAI1 | Y40: 1 | Z40: 11 | AA40: 21 | AB40: F.O. Supply, Inlet Press | AC40: -1 | AD40: 5 | AE40: bar | AF40: - | AG40: -0.2 | AH40: - | AI40: - | AJ40: 2 | AK40: F.O. Supply unit → MOCS control unit | AL40: -
B41: F.O. Supply unit | C41: PT102041 | D41: AI | E41: 4-20mA | F41: 2X2 | G41: 27 | H41: 28 | I41: 1C1 | J41: 23 | K41: 24 | R41: FS2 | X41: 1CAI1 | Y41: 2 | Z41: 12 | AA41: 22 | AB41: F.O. Supply, Outlet Press | AC41: 0 | AD41: 16 | AE41: bar | AF41: 4 | AG41: 5 | AH41: - | AI41: - | AJ41: 10 | AK41: F.O. Supply unit → MOCS control unit | AL41: -
B42: F.O. Supply unit | C42: FPS01-411 | D42: AO | E42: 4-20mA | I42: 1C1 | J42: 9 | K42: 10 | R42: FS3 | X42: 1CAO1 | Y42: 1 | Z42: 12 | AA42: 13 | AB42: F.O. Supply, pump motor Setpoint | AC42: 0 | AD42: 100 | AE42: % | AK42: MOCS control unit → F.O. Supply unit | AL42: -
...

Sheet No.# TB
B1: Skid | C1: Tag No. | D1: Signal type | F1: Internal power T/B | I1: External T/B | N1: Power T/B | Q1: MCCB | R1: Fuse | S1: Relay | X1: Module | AB1: Description | AC1: Range | AF1: Alarm | AK1: Connection point | AL1: Remark
A2: NO | B2: Skid | C2: Tag No. | D2: Signal type | E2: Signal type | F2: No. | G2: 24V | H2: 0V | I2: No. | J2: 24V | K2: (+) | L2: (-) | M2: 0V | N2: No. | O2: 24V | P2: 0V | S2: No. | T2: Contact | U2: GND | V2: 24V | W2: 0V | X2: No. | Y2: CH | Z2: (+) | AA2: (-) | AB2: Description | AC2: Min. | AD2: Max. | AE2: Unit | AF2: Low-Low | AG2: Low | AH2: High | AI2: High-High | AJ2: Delay | AK2: Connection point | AL2: Remark
B3: Internal connection | C3: MOC10-91#P | D3: DI | E3: N/C | F3: 9X# | G3: 1 | H3: 2 | I3: 1Y# | J3: 1 | M3: 2 | S3: EP# | V3: A1 | W3: A2 | X3: - | Y3: - | Z3: - | AA3: - | AB3: No.# MOCS Em'cy stop From panel | AC3: - | AD3: - | AE3: - | AF3: - | AG3: - | AH3: - | AI3: - | AJ3: - | AK3: Front door → MOCS control unit(Internal relay) | AL3: 0=Em'cy Stop
B4: Yard interface | C4: MOC10-91#E | D4: DI | E4: N/C | F4: 9X# | G4: 3 | H4: 4 | I4: 1Y# | J4: 3 | M4: 4 | S4: EE# | V4: A1 | W4: A2 | X4: - | Y4: - | Z4: - | AA4: - | AB4: No.# MOCS Em'cy stop From ECR | AC4: - | AD4: - | AE4: - | AF4: - | AG4: - | AH4: - | AI4: - | AJ4: - | AK4: Yard → MOCS control unit(Internal relay) | AL4: 0=Em'cy Stop
B5: Yard interface | C5: MOC10-91#B | D5: DI | E5: N/C | F5: 9X# | G5: 5 | H5: 6 | I5: 1Y# | J5: 5 | M5: 6 | S5: EB# | V5: A1 | W5: A2 | X5: - | Y5: - | Z5: - | AA5: - | AB5: No.# MOCS Em'cy stop From Bridge | AC5: - | AD5: - | AE5: - | AF5: - | AG5: - | AH5: - | AI5: - | AJ5: - | AK5: Yard → MOCS control unit(Internal relay) | AL5: 0=Em'cy Stop
B6: Internal connection | C6: MOC00-91#P | D6: DI | E6: N/C | F6: 9X# | G6: 7 | H6: 8 | I6: 3X# | J6: 1 | M6: 2 | S6: EP# | T6: N/O | U6: GND | V6: MOC10-91#P | W6: MOC10-91#P | X6: #DI1 | Y6: 3 | Z6: 12 | AB6: No.# MOCS Em'cy stop From panel (To module) | AC6: - | AD6: - | AE6: - | AF6: - | AG6: - | AH6: - | AI6: - | AJ6: - | AK6: Internal relay → IO module | AL6: 0=Em'cy Stop
B7: Internal connection | C7: MOC00-91#E | D7: DI | E7: N/C | F7: 9X# | G7: 9 | H7: 10 | I7: 3X# | J7: 3 | M7: 4 | S7: EE# | T7: N/O | U7: GND | V7: MOC10-91#E | W7: MOC10-91#E | X7: #DI1 | Y7: 4 | Z7: 22 | AB7: No.# MOCS Em'cy stop From ECR (To module) | AC7: - | AD7: - | AE7: - | AF7: - | AG7: - | AH7: - | AI7: - | AJ7: - | AK7: Internal relay → IO module | AL7: 0=Em'cy Stop
B8: Internal connection | C8: MOC00-91#B | D8: DI | E8: N/C | F8: 9X# | G8: 11 | H8: 12 | I8: 3X# | J8: 5 | M8: 6 | S8: EB# | T8: N/O | U8: GND | V8: MOC10-91#B | W8: MOC10-91#B | X8: #DI1 | Y8: 5 | Z8: 13 | AB8: No.# MOCS Em'cy stop From Bridge (To module) | AC8: - | AD8: - | AE8: - | AF8: - | AG8: - | AH8: - | AI8: - | AJ8: - | AK8: Internal relay → IO module | AL8: 0=Em'cy Stop
B9: Internal connection | C9: - | D9: DO | E9: N/C | I9: 3X# | K9: 9 | L9: 10 | S9: EV# | T9: N/O | U9: GND | V9: A1 | W9: A2 | X9: - | Y9: - | Z9: - | AA9: - | AB9: No.# RSV Forced open | AK9: Internal relay → Circuit | AL9: 0=Forced open
B10: Internal connection | C10: - | D10: DO | E10: N/C | I10: 3X# | K10: 11 | L10: 12 | S10: EV# | T10: N/O | U10: GND | V10: A1 | W10: A2 | X10: - | Y10: - | Z10: - | AA10: - | AB10: No.# RBV Forced open | AK10: Internal relay → Circuit | AL10: 0=Forced open
B11: Internal connection | C11: - | D11: DO | E11: N/C | I11: 3X# | K11: 13 | L11: 14 | S11: EV# | T11: N/O | U11: GND | V11: A1 | W11: A2 | X11: - | Y11: - | Z11: - | AA11: - | AB11: No.# RTV Forced open | AK11: Internal relay → Circuit | AL11: 0=Forced open
B12: Internal connection | C12: - | D12: DO | E12: N/C | I12: 3X# | K12: 15 | L12: 16 | S12: EV# | T12: N/O | U12: GND | V12: A1 | W12: A2 | X12: - | Y12: - | Z12: - | AA12: - | AB12: No.# SCR Valve Forced open | AK12: Internal relay → Circuit | AL12: 0=Forced open
B13: Internal connection | C13: MOC00-20# | D13: DI | E13: N/O | F13: 9X# | G13: 13 | H13: 14 | I13: 3X# | J13: 7 | K13: 8 | X13: #DI1 | Y13: 2 | Z13: 21 | AB13: No.# MOCS Remote/Local | AC13: - | AD13: - | AE13: - | AF13: - | AG13: - | AH13: - | AI13: - | AJ13: - | AK13: Front door → IO module | AL13: 1=Remote
B14: Yard interface | C14: ENG10-70# | D14: DI | E14: N/O | F14: 5X# | G14: 1 | H14: 2 | I14: 1Y# | J14: 7 | K14: 8 | X14: #DI1 | Y14: 1 | Z14: 11 | AB14: No.# G/E Low Sulfur fuel supplied (S=0.1%) | AC14: - | AD14: - | AE14: - | AF14: - | AG14: - | AH14: - | AI14: - | AJ14: - | AK14: Yard → MOCS control unit | AL14: 1=0.1% Sulfur
B15: Yard interface | C15: MOC10-11# | D15: DI | E15: N/O | F15: 5X# | G15: 3 | H15: 4 | I15: 1Y# | J15: 9 | K15: 10 | X15: #DI1 | Y15: 6 | Z15: 23 | AB15: No.# MOCS Start | AC15: - | AD15: - | AE15: - | AF15: - | AG15: - | AH15: - | AI15: - | AJ15: - | AK15: Yard → MOCS control unit | AL15: 1=Start
B16: Yard interface | C16: MBV10-11# | D16: DI | E16: N/O | F16: 5X# | G16: 5 | H16: 6 | I16: 1Y# | J16: 11 | K16: 12 | X16: #DI1 | Y16: 7 | Z16: 14 | AB16: No.# MOCS Preparation | AC16: - | AD16: - | AE16: - | AF16: - | AG16: - | AH16: - | AI16: - | AJ16: - | AK16: Yard → MOCS control unit | AL16: 1=Preparation
B17: Yard interface | C17: MOC10-01# | D17: DI | E17: N/O | F17: 5X# | G17: 7 | H17: 8 | I17: 1Y# | J17: 13 | K17: 14 | X17: #DI1 | Y17: 8 | Z17: 24 | AB17: No.# MOCS Stop | AC17: - | AD17: - | AE17: - | AF17: - | AG17: - | AH17: - | AI17: - | AJ17: - | AK17: Yard → MOCS control unit | AL17: 1=Stop
B18: Yard interface | C18: MOC11-20# | D18: DO | E18: N/O | F18: 5X# | G18: 9 | H18: 10 | I18: 1Y# | K18: 15 | L18: 16 | S18: #KY1 | T18: N/O | U18: GND | V18: A1 | W18: A2 | X18: #DO1 | Y18: 1 | Z18: 11 | AB18: No.# MOCS Ready | AC18: - | AD18: - | AE18: - | AF18: - | AG18: - | AH18: - | AI18: - | AJ18: - | AK18: MOCS control unit → Yard | AL18: 1=Ready
B19: Yard interface | C19: MBV11-22# | D19: DO | E19: N/O | F19: 5X# | G19: 11 | H19: 12 | I19: 1Y# | K19: 17 | L19: 18 | S19: #KY2 | T19: N/O | U19: GND | V19: A1 | W19: A2 | X19: #DO1 | Y19: 2 | Z19: 21 | AB19: No.# All Flow Through MOCS | AC19: - | AD19: - | AE19: - | AF19: - | AG19: - | AH19: - | AI19: - | AJ19: - | AK19: MOCS control unit → Yard | AL19: 1=All
B20: Yard interface | C20: MOC11-22# | D20: DO | E20: N/O | F20: 5X# | G20: 13 | H20: 14 | I20: 1Y# | K20: 19 | L20: 20 | S20: #KY3 | T20: N/O | U20: GND | V20: A1 | W20: A2 | X20: #DO1 | Y20: 3 | Z20: 12 | AB20: No.# MOCS Active | AC20: - | AD20: - | AE20: - | AF20: - | AG20: - | AH20: - | AI20: - | AJ20: - | AK20: MOCS control unit → Yard | AL20: 1=Active
B21: Yard interface | C21: MOC11-50# | D21: DO | E21: N/O | F21: 5X# | G21: 15 | H21: 16 | I21: 1Y# | K21: 21 | L21: 22 | S21: #KY4 | T21: N/O | U21: GND | V21: A1 | W21: A2 | X21: #DO1 | Y21: 4 | Z21: 22 | AB21: No.# MOCS F.O. Dosing system Flush Run | AC21: - | AD21: - | AE21: - | AF21: - | AG21: - | AH21: - | AI21: - | AJ21: - | AK21: MOCS control unit → Yard | AL21: 1=Flush
B22: F.O. Dosing unit | C22: TS103#42 | D22: DI | E22: N/C | F22: 6X# | G22: 1 | H22: 2 | I22: 2Y# | J22: 1 | K22: 2 | X22: #DI1 | Y22: 13 | Z22: 17 | AB22: No.# F.O. Dosing Fuel Oil Inlet Temp | AC22: - | AD22: - | AE22: - | AF22: - | AG22: - | AH22: - | AI22: - | AJ22: - | AK22: F.O. Dosing unit → MOCS control unit | AL22: 0 = 60℃ 이상
B23: F.O. Dosing unit | C23: ZV103#01 | D23: DO | E23: N/O | F23: 6X# | G23: 3 | H23: 4 | I23: 2Y# | J23: 3 | M23: 4 | N23: 4X# | O23: 1 | P23: 2 | S23: #KD1 | T23: N/O | U23: GND | V23: A1 | W23: A2 | X23: #DO1 | Y23: 5 | Z23: 13 | AB23: No.# F.O. Dosing Atomizing Air Sol. VV | AC23: - | AD23: - | AE23: - | AF23: - | AG23: - | AH23: - | AI23: - | AJ23: - | AK23: MOCS control unit → F.O. Dosing unit | AL23: 1=Open
