Workbook

Sheet Parameters
A1: R0.01 | B1: * Valve Error 관련 Parameter는 Alarm Parameter로 이동
A2: 25.05.07 | B2: MOCS Parameter list
A3: COSMO Page | B3: Category1 | C3: Category2 | D3: Category3 | E3: Index | F3: Name | G3: Description1 | H3: Description2 | I3: Default | J3: Range | M3: Scale | N3: Remark | O3: MATLAB Interface
J4: Min | K4: Max | L4: Unit
A5: 11 | B5: Common[0..199] | C5: System (Comm[0..49]) | D5: SystemType[0..3] (Comm[0..3]) | E5: 0 | F5: MOCSType | G5: 0: without SCR 1: with SCR 2: with SCR & bypass | H5: MOCS 승온 방식 선택 | I5: 1 | J5: 0 | K5: 10 | L5: - | M5: 1 | N5: ComboBox | O5: =CONCATENATE("IF_CommPara[",E5,"]") -> IF_CommPara[0]
A6: 11 | E6: 1 | F6: NumofGE | G6: Number of GE | H6: MOCS 승온 방식 선택 | I6: 1 | J6: 0 | K6: 8 | L6: - | M6: 1 | O6: =CONCATENATE("IF_CommPara[",E6,"]") -> IF_CommPara[1]
A7: 11 | E7: 2 | F7: HeatingSystem | G7: 0: F.O. Dosing System 1: Burner System | H7: MOCS 승온 방식 선택 | I7: 0 | J7: 0 | K7: 1 | L7: - | M7: 1 | N7: ComboBox | O7: =CONCATENATE("IF_CommPara[",E7,"]") -> IF_CommPara[2]
A8: 11 | E8: 3 | F8: FOSuppUnit | G8: 0: MOCS Controller 1: Yard | I8: 0 | J8: 0 | K8: 1 | L8: - | M8: 1 | N8: ComboBox | O8: =CONCATENATE("IF_CommPara[",E8,"]") -> IF_CommPara[3]
A9: - | D9: System Reserved[4..49] (Comm[4..49]) | E9: 4 | F9: SystemReserved4 | O9: =CONCATENATE("IF_CommPara[",E9,"]") -> IF_CommPara[4]
A10: - | E10: ... | F10: ... | O10: =CONCATENATE("IF_CommPara[",E10,"]") -> IF_CommPara[...]
A11: - | E11: 49 | F11: SystemReserved49 | O11: =CONCATENATE("IF_CommPara[",E11,"]") -> IF_CommPara[49]
A12: 11 | C12: State Flag (Comm[50..99]) | D12: MSS Normal Flag[0..4] (Comm[50..54]) | E12: 50 | F12: MOCSMinEngineLoad | G12: MOCS Ready Minimum Engine Load w/ MSS Active | H12: Engage State 진입 기준 Engine Load | I12: 20 | J12: 0 | K12: 120 | L12: % | M12: 100 | O12: =CONCATENATE("IF_CommPara[",E12,"]") -> IF_CommPara[50]
A13: 11 | E13: 51 | F13: MOCSReadyEngineLoad | G13: MOCS Ready Engine Load w/o MSS Active | H13: MSS Run signal 이 참에서 거짓으로 바뀔 때 Delay time 내 다시 참으로 돌아오면 신호를 참으로 유지 | I13: 50 | J13: 0 | K13: 120 | L13: % | M13: 100 | O13: =CONCATENATE("IF_CommPara[",E13,"]") -> IF_CommPara[51]
A14: 11 | E14: 52 | F14: MSSNormalFallingHysteresis | G14: Hysteresis for MSS Normal Flag to fall from True to False during MSS re-entry | I14: 5 | J14: 0 | K14: 120 | L14: % | M14: 100 | O14: =CONCATENATE("IF_CommPara[",E14,"]") -> IF_CommPara[52]
A15: 11 | E15: 53 | F15: MSSNormalFallingDelay | G15: Delay time for MSS Normal Flag to fall from True to False during MSS re-entry | H15: MSS Run signal 이 참에서 거짓으로 바뀔 때 Delay time 내 다시 참으로 돌아오면 신호를 참으로 유지 | I15: 10 | J15: 0 | K15: 100 | L15: sec | M15: 10 | O15: =CONCATENATE("IF_CommPara[",E15,"]") -> IF_CommPara[53]
A16: - | E16: 54 | F16: MSSFlagReserved4 | O16: =CONCATENATE("IF_CommPara[",E16,"]") -> IF_CommPara[54]
A17: 11 | D17: Load Change Flag[0..4] (Comm[55..59]) | E17: 55 | F17: MovAvgPeriod | G17: Moving average sampling period | I17: 1 | J17: 0 | K17: 10 | L17: sec | M17: 10 | O17: =CONCATENATE("IF_CommPara[",E17,"]") -> IF_CommPara[55]
A18: 11 | E18: 56 | F18: ComparePoint | G18: Moving average compare point | I18: 1 | J18: 0 | K18: 10 | L18: sec | M18: 10 | O18: =CONCATENATE("IF_CommPara[",E18,"]") -> IF_CommPara[56]
A19: 11 | E19: 57 | F19: LoadChangeThreshold | G19: Load change detection threshold | I19: 5 | J19: 0 | K19: 1000 | L19: %/sec | M19: 10 | O19: =CONCATENATE("IF_CommPara[",E19,"]") -> IF_CommPara[57]
A20: 11 | E20: 58 | F20: LoadCangeFlagFallingDelay | G20: Load Cange Flag Falling Delay | I20: 180 | J20: 0 | K20: 3600 | L20: sec | M20: 100 | O20: =CONCATENATE("IF_CommPara[",E20,"]") -> IF_CommPara[58]
A21: - | E21: 59 | F21: LoadCangeFlagReserved4 | O21: =CONCATENATE("IF_CommPara[",E21,"]") -> IF_CommPara[59]
A22: 11 | D22: System Warmed Up Flag[0..4] (Comm[60..64]) | E22: 60 | F22: WarmUpDTemp | G22: (T/C outlet temp. - MOCS chamber inlet temp.) < HUReadyDTemp | H22: Active State 진입 기준 시스템 온도차 | I22: 50 | J22: 0 | K22: 800 | L22: degC | M22: 10 | O22: =CONCATENATE("IF_CommPara[",E22,"]") -> IF_CommPara[60]
A23: 11 | E23: 61 | F23: WarmUpITemp | G23: Mixer Inlet Temp > [HUReadyHUITemp] | H23: Active State 진입 기준 Chamber Inlet 온도 | I23: 300 | J23: 0 | K23: 800 | L23: degC | M23: 10 | O23: =CONCATENATE("IF_CommPara[",E23,"]") -> IF_CommPara[61]
A24: 11 | E24: 62 | F24: WarmUpChITemp | G24: Chamber Inlet01 Temp > [HUReadyChITemp] | H24: Active State 진입 기준 Chamber Mid 온도 | I24: 300 | J24: 0 | K24: 800 | L24: degC | M24: 10 | O24: =CONCATENATE("IF_CommPara[",E24,"]") -> IF_CommPara[62]
A25: 11 | E25: 63 | F25: WarmUpChMTemp | G25: Chamber Mid01 Temp > [HUReadyChMTemp] | H25: Active State 진입 기준 Chamber Outlet 온도 | I25: 300 | J25: 0 | K25: 800 | L25: degC | M25: 10 | O25: =CONCATENATE("IF_CommPara[",E25,"]") -> IF_CommPara[63]
A26: 11 | E26: 64 | F26: WarmUpChOTemp | G26: Chamber Outlet01 Temp > [HUReadyChOTemp] | H26: Active State 진입 기준 Mixer Inlet(Heating Unit Inlet)온도 | I26: 300 | J26: 0 | K26: 800 | L26: degC | M26: 10 | O26: =CONCATENATE("IF_CommPara[",E26,"]") -> IF_CommPara[64]
A27: - | D27: Flag Reserved[0..34] (Comm[65..99]) | E27: 65 | F27: FlagReserved15 | O27: =CONCATENATE("IF_CommPara[",E27,"]") -> IF_CommPara[65]
A28: - | E28: ... | F28: ... | O28: =CONCATENATE("IF_CommPara[",E28,"]") -> IF_CommPara[...]
A29: - | E29: 99 | F29: FlagReserved49 | O29: =CONCATENATE("IF_CommPara[",E29,"]") -> IF_CommPara[99]
A30: - | C30: Main (Comm[100..149]) | D30: Init[0..4] (Comm[100..104]) | E30: 100 | F30: InitReserved0 | I30: 0 | J30: 0 | K30: 1000 | L30: - | M30: 1 | O30: =CONCATENATE("IF_CommPara[",E30,"]") -> IF_CommPara[100]
A31: - | E31: 101 | F31: InitReserved1 | I31: 0 | J31: 0 | K31: 1000 | L31: - | M31: 1 | O31: =CONCATENATE("IF_CommPara[",E31,"]") -> IF_CommPara[101]
A32: - | E32: 102 | F32: InitReserved2 | I32: 0 | J32: 0 | K32: 1000 | L32: - | M32: 1 | O32: =CONCATENATE("IF_CommPara[",E32,"]") -> IF_CommPara[102]
A33: - | E33: 103 | F33: InitReserved3 | I33: 0 | J33: 0 | K33: 1000 | L33: - | M33: 1 | O33: =CONCATENATE("IF_CommPara[",E33,"]") -> IF_CommPara[103]
A34: - | E34: 104 | F34: InitReserved4 | I34: 0 | J34: 0 | K34: 1000 | L34: - | M34: 1 | O34: =CONCATENATE("IF_CommPara[",E34,"]") -> IF_CommPara[104]
A35: 11 | D35: Sealing[0..9] (Comm[105..114]) | E35: 105 | F35: VSSolValveOpenDP | G35: VS sol valve Open dP | H35: V&S Valve Open 하는 RTV PDT 압력 | I35: 10 | J35: 0 | K35: 100 | L35: mbar | M35: 100 | N35: 비활성화: (HeatingSystem == Burner) & (VentingSealingUnit == Not Availavle) | O35: =CONCATENATE("IF_CommPara[",E35,"]") -> IF_CommPara[105]
A36: 11 | E36: 106 | F36: VSSolValveCloseDP | G36: VS sol valve Close dP | H36: V&S Valve Close 하는 RTV PDT 압력 | I36: 20 | J36: 0 | K36: 100 | L36: mbar | M36: 100 | N36: 비활성화: (HeatingSystem == Burner) & (VentingSealingUnit == Not Availavle) | O36: =CONCATENATE("IF_CommPara[",E36,"]") -> IF_CommPara[106]
A37: 11 | E37: 107 | F37: RTVOpenDP | G37: RTV Open dP | H37: RTV Open하는 RTV PDT압력 | I37: 45 | J37: 0 | K37: 100 | L37: mbar | M37: 100 | O37: =CONCATENATE("IF_CommPara[",E37,"]") -> IF_CommPara[107]
A38: 11 | E38: 108 | F38: RTVCloseDP | G38: RTV Close dP | H38: RTV Close하는 RTV PDT압력 | I38: 30 | J38: 0 | K38: 100 | L38: mbar | M38: 100 | O38: =CONCATENATE("IF_CommPara[",E38,"]") -> IF_CommPara[108]
A39: 11 | E39: 109 | F39: SealRTVSetpoint | G39: RTV Open Target Position on Sealing State | H39: Sealing State, RTV Open dP에서 RTV 개도량 | I39: 10 | J39: 0 | K39: 100 | L39: % | M39: 100 | O39: =CONCATENATE("IF_CommPara[",E39,"]") -> IF_CommPara[109]
A40: 11 | E40: 110 | F40: VSSolValveOpenDuration | G40: VS Sol Valve Open duration on Sealing State | I40: 5 | J40: 0 | K40: 10 | L40: sec | M40: 10 | O40: =CONCATENATE("IF_CommPara[",E40,"]") -> IF_CommPara[110]
...

Sheet AS_Struct
A1: Category1 | F1: Category2 | K1: Category3
A2: var | C2: typ | D2: struct | E2: val | F2: var | H2: typ | I2: struct | J2: val | K2: var | M2: typ | N2: struct | O2: val
A3: =SUBSTITUTE(LEFT(Parameters!B5,IF(IFERROR(FIND("[",Parameters!B5),100)>IFERROR(FIND("(",Parameters!B5),100),IFERROR(FIND("(",Parameters!B5),100),IFERROR(FIND("[",Parameters!B5),100))-1)," ","") -> Common | B3: {=_xlfn.UNIQUE(A3:A192)} -> Common | C3: =IF(B3="","",_xlfn.CONCAT(B3,"_typ")) -> Common_typ | D3: =IF(C3 = "","",_xlfn.CONCAT(C3," : STRUCT END_STRUCT;")) -> Common_typ : STRUCT END_STRUCT; | E3: =IF(B3="","",_xlfn.CONCAT(B3," : ",C3,";")) -> Common : Common_typ; | F3: =SUBSTITUTE(LEFT(Parameters!C5,IF(IFERROR(FIND("[",Parameters!C5),100)>IFERROR(FIND("(",Parameters!C5),100),IFERROR(FIND("(",Parameters!C5),100),IFERROR(FIND("[",Parameters!C5),100))-1)," ","") -> System | G3: {=_xlfn.UNIQUE(F3:F192)} -> System | H3: =IF(G3="","",_xlfn.CONCAT(G3,"_typ")) -> System _typ | I3: =IF(H3 = "","",_xlfn.CONCAT(H3," : STRUCT END_STRUCT;")) -> System _typ : STRUCT END_STRUCT; | J3: =IF(G3="","",_xlfn.CONCAT(G3," : ",H3,";")) -> System : System _typ; | K3: =SUBSTITUTE(LEFT(Parameters!D5,IF(IFERROR(FIND("[",Parameters!D5),100)>IFERROR(FIND("(",Parameters!D5),100),IFERROR(FIND("(",Parameters!D5),100),IFERROR(FIND("[",Parameters!D5),100))-1)," ","") -> SystemType | L3: {=_xlfn.UNIQUE(K3:K192)} -> SystemType | M3: =IF(L3="","",_xlfn.CONCAT(L3,"_typ")) -> SystemType_typ | N3: =IF(M3 = "","",_xlfn.CONCAT(M3," : STRUCT END_STRUCT;")) -> SystemType_typ : STRUCT END_STRUCT; | O3: =IF(L3="","",_xlfn.CONCAT(L3," : ",M3,";")) -> SystemType : SystemType_typ; | P3: =K3 -> SystemType | Q3: =Parameters!E5 -> 0 | R3: =Parameters!F5 -> MOCSType | S3: =IF(R3 = "","",_xlfn.CONCAT(R3," : REAL;")) -> MOCSType : REAL; | U3: SystemReserved4 | V3: =IF(U3 = "","",_xlfn.CONCAT(U3," : REAL;")) -> SystemReserved4 : REAL;
A4: =SUBSTITUTE(LEFT(Parameters!B6,IF(IFERROR(FIND("[",Parameters!B6),100)>IFERROR(FIND("(",Parameters!B6),100),IFERROR(FIND("(",Parameters!B6),100),IFERROR(FIND("[",Parameters!B6),100))-1)," ","") | C4: =IF(B4="","",_xlfn.CONCAT(B4,"_typ")) | D4: =IF(C4 = "","",_xlfn.CONCAT(C4," : STRUCT END_STRUCT;")) | E4: =IF(B4="","",_xlfn.CONCAT(B4," : ",C4,";")) | F4: =SUBSTITUTE(LEFT(Parameters!C6,IF(IFERROR(FIND("[",Parameters!C6),100)>IFERROR(FIND("(",Parameters!C6),100),IFERROR(FIND("(",Parameters!C6),100),IFERROR(FIND("[",Parameters!C6),100))-1)," ","") | H4: =IF(G4="","",_xlfn.CONCAT(G4,"_typ")) | I4: =IF(H4 = "","",_xlfn.CONCAT(H4," : STRUCT END_STRUCT;")) | J4: =IF(G4="","",_xlfn.CONCAT(G4," : ",H4,";")) | K4: =SUBSTITUTE(LEFT(Parameters!D6,IF(IFERROR(FIND("[",Parameters!D6),100)>IFERROR(FIND("(",Parameters!D6),100),IFERROR(FIND("(",Parameters!D6),100),IFERROR(FIND("[",Parameters!D6),100))-1)," ","") | M4: =IF(L4="","",_xlfn.CONCAT(L4,"_typ")) | N4: =IF(M4 = "","",_xlfn.CONCAT(M4," : STRUCT END_STRUCT;")) | O4: =IF(L4="","",_xlfn.CONCAT(L4," : ",M4,";")) | P4: =K4 | Q4: =Parameters!E6 -> 1 | R4: =Parameters!F6 -> NumofGE | S4: =IF(R4 = "","",_xlfn.CONCAT(R4," : REAL;")) -> NumofGE : REAL; | U4: SystemReserved5 | V4: =IF(U4 = "","",_xlfn.CONCAT(U4," : REAL;")) -> SystemReserved5 : REAL;
A5: =SUBSTITUTE(LEFT(Parameters!B7,IF(IFERROR(FIND("[",Parameters!B7),100)>IFERROR(FIND("(",Parameters!B7),100),IFERROR(FIND("(",Parameters!B7),100),IFERROR(FIND("[",Parameters!B7),100))-1)," ","") | B5: Indiv | C5: =IF(B5="","",_xlfn.CONCAT(B5,"_typ")) -> Indiv_typ | D5: =IF(C5 = "","",_xlfn.CONCAT(C5," : STRUCT END_STRUCT;")) -> Indiv_typ : STRUCT END_STRUCT; | E5: =IF(B5="","",_xlfn.CONCAT(B5," : ",C5,";")) -> Indiv : Indiv_typ; | F5: =SUBSTITUTE(LEFT(Parameters!C7,IF(IFERROR(FIND("[",Parameters!C7),100)>IFERROR(FIND("(",Parameters!C7),100),IFERROR(FIND("(",Parameters!C7),100),IFERROR(FIND("[",Parameters!C7),100))-1)," ","") | G5: StateFlag | H5: =IF(G5="","",_xlfn.CONCAT(G5,"_typ")) -> StateFlag _typ | I5: =IF(H5 = "","",_xlfn.CONCAT(H5," : STRUCT END_STRUCT;")) -> StateFlag _typ : STRUCT END_STRUCT; | J5: =IF(G5="","",_xlfn.CONCAT(G5," : ",H5,";")) -> StateFlag : StateFlag _typ; | K5: =SUBSTITUTE(LEFT(Parameters!D7,IF(IFERROR(FIND("[",Parameters!D7),100)>IFERROR(FIND("(",Parameters!D7),100),IFERROR(FIND("(",Parameters!D7),100),IFERROR(FIND("[",Parameters!D7),100))-1)," ","") | L5: SystemReserved | M5: =IF(L5="","",_xlfn.CONCAT(L5,"_typ")) -> SystemReserved_typ | N5: =IF(M5 = "","",_xlfn.CONCAT(M5," : STRUCT END_STRUCT;")) -> SystemReserved_typ : STRUCT END_STRUCT; | O5: =IF(L5="","",_xlfn.CONCAT(L5," : ",M5,";")) -> SystemReserved : SystemReserved_typ; | P5: =K5 | Q5: =Parameters!E7 -> 2 | R5: =Parameters!F7 -> HeatingSystem | S5: =IF(R5 = "","",_xlfn.CONCAT(R5," : REAL;")) -> HeatingSystem : REAL; | U5: SystemReserved6 | V5: =IF(U5 = "","",_xlfn.CONCAT(U5," : REAL;")) -> SystemReserved6 : REAL;
A6: =SUBSTITUTE(LEFT(Parameters!B8,IF(IFERROR(FIND("[",Parameters!B8),100)>IFERROR(FIND("(",Parameters!B8),100),IFERROR(FIND("(",Parameters!B8),100),IFERROR(FIND("[",Parameters!B8),100))-1)," ","") | C6: =IF(B6="","",_xlfn.CONCAT(B6,"_typ")) | D6: =IF(C6 = "","",_xlfn.CONCAT(C6," : STRUCT END_STRUCT;")) | E6: =IF(B6="","",_xlfn.CONCAT(B6," : ",C6,";")) | F6: =SUBSTITUTE(LEFT(Parameters!C8,IF(IFERROR(FIND("[",Parameters!C8),100)>IFERROR(FIND("(",Parameters!C8),100),IFERROR(FIND("(",Parameters!C8),100),IFERROR(FIND("[",Parameters!C8),100))-1)," ","") | G6: Main | H6: =IF(G6="","",_xlfn.CONCAT(G6,"_typ")) -> Main _typ | I6: =IF(H6 = "","",_xlfn.CONCAT(H6," : STRUCT END_STRUCT;")) -> Main _typ : STRUCT END_STRUCT; | J6: =IF(G6="","",_xlfn.CONCAT(G6," : ",H6,";")) -> Main : Main _typ; | K6: =SUBSTITUTE(LEFT(Parameters!D8,IF(IFERROR(FIND("[",Parameters!D8),100)>IFERROR(FIND("(",Parameters!D8),100),IFERROR(FIND("(",Parameters!D8),100),IFERROR(FIND("[",Parameters!D8),100))-1)," ","") | L6: MSSNormalFlag | M6: =IF(L6="","",_xlfn.CONCAT(L6,"_typ")) -> MSSNormalFlag_typ | N6: =IF(M6 = "","",_xlfn.CONCAT(M6," : STRUCT END_STRUCT;")) -> MSSNormalFlag_typ : STRUCT END_STRUCT; | O6: =IF(L6="","",_xlfn.CONCAT(L6," : ",M6,";")) -> MSSNormalFlag : MSSNormalFlag_typ; | P6: =K6 | Q6: =Parameters!E8 -> 3 | R6: =Parameters!F8 -> FOSuppUnit | S6: =IF(R6 = "","",_xlfn.CONCAT(R6," : REAL;")) -> FOSuppUnit : REAL; | U6: SystemReserved7 | V6: =IF(U6 = "","",_xlfn.CONCAT(U6," : REAL;")) -> SystemReserved7 : REAL;
A7: =SUBSTITUTE(LEFT(Parameters!B9,IF(IFERROR(FIND("[",Parameters!B9),100)>IFERROR(FIND("(",Parameters!B9),100),IFERROR(FIND("(",Parameters!B9),100),IFERROR(FIND("[",Parameters!B9),100))-1)," ","") | C7: =IF(B7="","",_xlfn.CONCAT(B7,"_typ")) | D7: =IF(C7 = "","",_xlfn.CONCAT(C7," : STRUCT END_STRUCT;")) | E7: =IF(B7="","",_xlfn.CONCAT(B7," : ",C7,";")) | F7: =SUBSTITUTE(LEFT(Parameters!C9,IF(IFERROR(FIND("[",Parameters!C9),100)>IFERROR(FIND("(",Parameters!C9),100),IFERROR(FIND("(",Parameters!C9),100),IFERROR(FIND("[",Parameters!C9),100))-1)," ","") | G7: FODS | H7: =IF(G7="","",_xlfn.CONCAT(G7,"_typ")) -> FODS_typ | I7: =IF(H7 = "","",_xlfn.CONCAT(H7," : STRUCT END_STRUCT;")) -> FODS_typ : STRUCT END_STRUCT; | J7: =IF(G7="","",_xlfn.CONCAT(G7," : ",H7,";")) -> FODS : FODS_typ; | K7: =SUBSTITUTE(LEFT(Parameters!D9,IF(IFERROR(FIND("[",Parameters!D9),100)>IFERROR(FIND("(",Parameters!D9),100),IFERROR(FIND("(",Parameters!D9),100),IFERROR(FIND("[",Parameters!D9),100))-1)," ","") -> SystemReserved | L7: LoadChangeFlag | M7: =IF(L7="","",_xlfn.CONCAT(L7,"_typ")) -> LoadChangeFlag_typ | N7: =IF(M7 = "","",_xlfn.CONCAT(M7," : STRUCT END_STRUCT;")) -> LoadChangeFlag_typ : STRUCT END_STRUCT; | O7: =IF(L7="","",_xlfn.CONCAT(L7," : ",M7,";")) -> LoadChangeFlag : LoadChangeFlag_typ; | P7: =K7 -> SystemReserved | Q7: =Parameters!E9 -> 4 | R7: =Parameters!F9 -> SystemReserved4 | S7: =IF(R7 = "","",_xlfn.CONCAT(R7," : REAL;")) -> SystemReserved4 : REAL; | U7: SystemReserved8 | V7: =IF(U7 = "","",_xlfn.CONCAT(U7," : REAL;")) -> SystemReserved8 : REAL;
A8: =SUBSTITUTE(LEFT(Parameters!B10,IF(IFERROR(FIND("[",Parameters!B10),100)>IFERROR(FIND("(",Parameters!B10),100),IFERROR(FIND("(",Parameters!B10),100),IFERROR(FIND("[",Parameters!B10),100))-1)," ","") | C8: =IF(B8="","",_xlfn.CONCAT(B8,"_typ")) | D8: =IF(C8 = "","",_xlfn.CONCAT(C8," : STRUCT END_STRUCT;")) | E8: =IF(B8="","",_xlfn.CONCAT(B8," : ",C8,";")) | F8: =SUBSTITUTE(LEFT(Parameters!C10,IF(IFERROR(FIND("[",Parameters!C10),100)>IFERROR(FIND("(",Parameters!C10),100),IFERROR(FIND("(",Parameters!C10),100),IFERROR(FIND("[",Parameters!C10),100))-1)," ","") | G8: CommonReservedCat2 | H8: =IF(G8="","",_xlfn.CONCAT(G8,"_typ")) -> CommonReservedCat2_typ | I8: =IF(H8 = "","",_xlfn.CONCAT(H8," : STRUCT END_STRUCT;")) -> CommonReservedCat2_typ : STRUCT END_STRUCT; | J8: =IF(G8="","",_xlfn.CONCAT(G8," : ",H8,";")) -> CommonReservedCat2 : CommonReservedCat2_typ; | K8: =SUBSTITUTE(LEFT(Parameters!D10,IF(IFERROR(FIND("[",Parameters!D10),100)>IFERROR(FIND("(",Parameters!D10),100),IFERROR(FIND("(",Parameters!D10),100),IFERROR(FIND("[",Parameters!D10),100))-1)," ","") | L8: SystemWarmedUpFlag | M8: =IF(L8="","",_xlfn.CONCAT(L8,"_typ")) -> SystemWarmedUpFlag_typ | N8: =IF(M8 = "","",_xlfn.CONCAT(M8," : STRUCT END_STRUCT;")) -> SystemWarmedUpFlag_typ : STRUCT END_STRUCT; | O8: =IF(L8="","",_xlfn.CONCAT(L8," : ",M8,";")) -> SystemWarmedUpFlag : SystemWarmedUpFlag_typ; | P8: =K8 | Q8: =Parameters!E10 -> ... | R8: =Parameters!F10 -> ... | S8: =IF(R8 = "","",_xlfn.CONCAT(R8," : REAL;")) -> ... : REAL; | U8: SystemReserved9 | V8: =IF(U8 = "","",_xlfn.CONCAT(U8," : REAL;")) -> SystemReserved9 : REAL;
A9: =SUBSTITUTE(LEFT(Parameters!B11,IF(IFERROR(FIND("[",Parameters!B11),100)>IFERROR(FIND("(",Parameters!B11),100),IFERROR(FIND("(",Parameters!B11),100),IFERROR(FIND("[",Parameters!B11),100))-1)," ","") | C9: =IF(B9="","",_xlfn.CONCAT(B9,"_typ")) | D9: =IF(C9 = "","",_xlfn.CONCAT(C9," : STRUCT END_STRUCT;")) | E9: =IF(B9="","",_xlfn.CONCAT(B9," : ",C9,";")) | F9: =SUBSTITUTE(LEFT(Parameters!C11,IF(IFERROR(FIND("[",Parameters!C11),100)>IFERROR(FIND("(",Parameters!C11),100),IFERROR(FIND("(",Parameters!C11),100),IFERROR(FIND("[",Parameters!C11),100))-1)," ","") | G9: FODSFeedforward | H9: =IF(G9="","",_xlfn.CONCAT(G9,"_typ")) -> FODSFeedforward_typ | I9: =IF(H9 = "","",_xlfn.CONCAT(H9," : STRUCT END_STRUCT;")) -> FODSFeedforward_typ : STRUCT END_STRUCT; | J9: =IF(G9="","",_xlfn.CONCAT(G9," : ",H9,";")) -> FODSFeedforward : FODSFeedforward_typ; | K9: =SUBSTITUTE(LEFT(Parameters!D11,IF(IFERROR(FIND("[",Parameters!D11),100)>IFERROR(FIND("(",Parameters!D11),100),IFERROR(FIND("(",Parameters!D11),100),IFERROR(FIND("[",Parameters!D11),100))-1)," ","") | L9: FlagReserved | M9: =IF(L9="","",_xlfn.CONCAT(L9,"_typ")) -> FlagReserved_typ | N9: =IF(M9 = "","",_xlfn.CONCAT(M9," : STRUCT END_STRUCT;")) -> FlagReserved_typ : STRUCT END_STRUCT; | O9: =IF(L9="","",_xlfn.CONCAT(L9," : ",M9,";")) -> FlagReserved : FlagReserved_typ; | P9: =K9 | Q9: =Parameters!E11 -> 49 | R9: =Parameters!F11 -> SystemReserved49 | S9: =IF(R9 = "","",_xlfn.CONCAT(R9," : REAL;")) -> SystemReserved49 : REAL; | U9: SystemReserved10 | V9: =IF(U9 = "","",_xlfn.CONCAT(U9," : REAL;")) -> SystemReserved10 : REAL;
A10: =SUBSTITUTE(LEFT(Parameters!B12,IF(IFERROR(FIND("[",Parameters!B12),100)>IFERROR(FIND("(",Parameters!B12),100),IFERROR(FIND("(",Parameters!B12),100),IFERROR(FIND("[",Parameters!B12),100))-1)," ","") | C10: =IF(B10="","",_xlfn.CONCAT(B10,"_typ")) | D10: =IF(C10 = "","",_xlfn.CONCAT(C10," : STRUCT END_STRUCT;")) | E10: =IF(B10="","",_xlfn.CONCAT(B10," : ",C10,";")) | F10: =SUBSTITUTE(LEFT(Parameters!C12,IF(IFERROR(FIND("[",Parameters!C12),100)>IFERROR(FIND("(",Parameters!C12),100),IFERROR(FIND("(",Parameters!C12),100),IFERROR(FIND("[",Parameters!C12),100))-1)," ","") -> StateFlag | G10: FODSFeedback | H10: =IF(G10="","",_xlfn.CONCAT(G10,"_typ")) -> FODSFeedback_typ | I10: =IF(H10 = "","",_xlfn.CONCAT(H10," : STRUCT END_STRUCT;")) -> FODSFeedback_typ : STRUCT END_STRUCT; | J10: =IF(G10="","",_xlfn.CONCAT(G10," : ",H10,";")) -> FODSFeedback : FODSFeedback_typ; | K10: =SUBSTITUTE(LEFT(Parameters!D12,IF(IFERROR(FIND("[",Parameters!D12),100)>IFERROR(FIND("(",Parameters!D12),100),IFERROR(FIND("(",Parameters!D12),100),IFERROR(FIND("[",Parameters!D12),100))-1)," ","") -> MSSNormalFlag | L10: Init | M10: =IF(L10="","",_xlfn.CONCAT(L10,"_typ")) -> Init_typ | N10: =IF(M10 = "","",_xlfn.CONCAT(M10," : STRUCT END_STRUCT;")) -> Init_typ : STRUCT END_STRUCT; | O10: =IF(L10="","",_xlfn.CONCAT(L10," : ",M10,";")) -> Init : Init_typ; | P10: =K10 -> MSSNormalFlag | Q10: =Parameters!E12 -> 50 | R10: =Parameters!F12 -> MOCSMinEngineLoad | S10: =IF(R10 = "","",_xlfn.CONCAT(R10," : REAL;")) -> MOCSMinEngineLoad : REAL; | U10: SystemReserved11 | V10: =IF(U10 = "","",_xlfn.CONCAT(U10," : REAL;")) -> SystemReserved11 : REAL;
A11: =SUBSTITUTE(LEFT(Parameters!B13,IF(IFERROR(FIND("[",Parameters!B13),100)>IFERROR(FIND("(",Parameters!B13),100),IFERROR(FIND("(",Parameters!B13),100),IFERROR(FIND("[",Parameters!B13),100))-1)," ","") | C11: =IF(B11="","",_xlfn.CONCAT(B11,"_typ")) | D11: =IF(C11 = "","",_xlfn.CONCAT(C11," : STRUCT END_STRUCT;")) | E11: =IF(B11="","",_xlfn.CONCAT(B11," : ",C11,";")) | F11: =SUBSTITUTE(LEFT(Parameters!C13,IF(IFERROR(FIND("[",Parameters!C13),100)>IFERROR(FIND("(",Parameters!C13),100),IFERROR(FIND("(",Parameters!C13),100),IFERROR(FIND("[",Parameters!C13),100))-1)," ","") | G11: IndivReservedCat2 | H11: =IF(G11="","",_xlfn.CONCAT(G11,"_typ")) -> IndivReservedCat2 _typ | I11: =IF(H11 = "","",_xlfn.CONCAT(H11," : STRUCT END_STRUCT;")) -> IndivReservedCat2 _typ : STRUCT END_STRUCT; | J11: =IF(G11="","",_xlfn.CONCAT(G11," : ",H11,";")) -> IndivReservedCat2 : IndivReservedCat2 _typ; | K11: =SUBSTITUTE(LEFT(Parameters!D13,IF(IFERROR(FIND("[",Parameters!D13),100)>IFERROR(FIND("(",Parameters!D13),100),IFERROR(FIND("(",Parameters!D13),100),IFERROR(FIND("[",Parameters!D13),100))-1)," ","") | L11: Sealing | M11: =IF(L11="","",_xlfn.CONCAT(L11,"_typ")) -> Sealing_typ | N11: =IF(M11 = "","",_xlfn.CONCAT(M11," : STRUCT END_STRUCT;")) -> Sealing_typ : STRUCT END_STRUCT; | O11: =IF(L11="","",_xlfn.CONCAT(L11," : ",M11,";")) -> Sealing : Sealing_typ; | P11: =K11 | Q11: =Parameters!E13 -> 51 | R11: =Parameters!F13 -> MOCSReadyEngineLoad | S11: =IF(R11 = "","",_xlfn.CONCAT(R11," : REAL;")) -> MOCSReadyEngineLoad : REAL; | U11: SystemReserved12 | V11: =IF(U11 = "","",_xlfn.CONCAT(U11," : REAL;")) -> SystemReserved12 : REAL;
A12: =SUBSTITUTE(LEFT(Parameters!B14,IF(IFERROR(FIND("[",Parameters!B14),100)>IFERROR(FIND("(",Parameters!B14),100),IFERROR(FIND("(",Parameters!B14),100),IFERROR(FIND("[",Parameters!B14),100))-1)," ","") | C12: =IF(B12="","",_xlfn.CONCAT(B12,"_typ")) | D12: =IF(C12 = "","",_xlfn.CONCAT(C12," : STRUCT END_STRUCT;")) | E12: =IF(B12="","",_xlfn.CONCAT(B12," : ",C12,";")) | F12: =SUBSTITUTE(LEFT(Parameters!C14,IF(IFERROR(FIND("[",Parameters!C14),100)>IFERROR(FIND("(",Parameters!C14),100),IFERROR(FIND("(",Parameters!C14),100),IFERROR(FIND("[",Parameters!C14),100))-1)," ","") | H12: =IF(G12="","",_xlfn.CONCAT(G12,"_typ")) | I12: =IF(H12 = "","",_xlfn.CONCAT(H12," : STRUCT END_STRUCT;")) | J12: =IF(G12="","",_xlfn.CONCAT(G12," : ",H12,";")) | K12: =SUBSTITUTE(LEFT(Parameters!D14,IF(IFERROR(FIND("[",Parameters!D14),100)>IFERROR(FIND("(",Parameters!D14),100),IFERROR(FIND("(",Parameters!D14),100),IFERROR(FIND("[",Parameters!D14),100))-1)," ","") | L12: Engage | M12: =IF(L12="","",_xlfn.CONCAT(L12,"_typ")) -> Engage_typ | N12: =IF(M12 = "","",_xlfn.CONCAT(M12," : STRUCT END_STRUCT;")) -> Engage_typ : STRUCT END_STRUCT; | O12: =IF(L12="","",_xlfn.CONCAT(L12," : ",M12,";")) -> Engage : Engage_typ; | P12: =K12 | Q12: =Parameters!E14 -> 52 | R12: =Parameters!F14 -> MSSNormalFallingHysteresis | S12: =IF(R12 = "","",_xlfn.CONCAT(R12," : REAL;")) -> MSSNormalFallingHysteresis : REAL; | U12: SystemReserved13 | V12: =IF(U12 = "","",_xlfn.CONCAT(U12," : REAL;")) -> SystemReserved13 : REAL;
A13: =SUBSTITUTE(LEFT(Parameters!B15,IF(IFERROR(FIND("[",Parameters!B15),100)>IFERROR(FIND("(",Parameters!B15),100),IFERROR(FIND("(",Parameters!B15),100),IFERROR(FIND("[",Parameters!B15),100))-1)," ","") | C13: =IF(B13="","",_xlfn.CONCAT(B13,"_typ")) | D13: =IF(C13 = "","",_xlfn.CONCAT(C13," : STRUCT END_STRUCT;")) | E13: =IF(B13="","",_xlfn.CONCAT(B13," : ",C13,";")) | F13: =SUBSTITUTE(LEFT(Parameters!C15,IF(IFERROR(FIND("[",Parameters!C15),100)>IFERROR(FIND("(",Parameters!C15),100),IFERROR(FIND("(",Parameters!C15),100),IFERROR(FIND("[",Parameters!C15),100))-1)," ","") | H13: =IF(G13="","",_xlfn.CONCAT(G13,"_typ")) | I13: =IF(H13 = "","",_xlfn.CONCAT(H13," : STRUCT END_STRUCT;")) | J13: =IF(G13="","",_xlfn.CONCAT(G13," : ",H13,";")) | K13: =SUBSTITUTE(LEFT(Parameters!D15,IF(IFERROR(FIND("[",Parameters!D15),100)>IFERROR(FIND("(",Parameters!D15),100),IFERROR(FIND("(",Parameters!D15),100),IFERROR(FIND("[",Parameters!D15),100))-1)," ","") | L13: Active | M13: =IF(L13="","",_xlfn.CONCAT(L13,"_typ")) -> Active_typ | N13: =IF(M13 = "","",_xlfn.CONCAT(M13," : STRUCT END_STRUCT;")) -> Active_typ : STRUCT END_STRUCT; | O13: =IF(L13="","",_xlfn.CONCAT(L13," : ",M13,";")) -> Active : Active_typ; | P13: =K13 | Q13: =Parameters!E15 -> 53 | R13: =Parameters!F15 -> MSSNormalFallingDelay | S13: =IF(R13 = "","",_xlfn.CONCAT(R13," : REAL;")) -> MSSNormalFallingDelay : REAL; | U13: SystemReserved14 | V13: =IF(U13 = "","",_xlfn.CONCAT(U13," : REAL;")) -> SystemReserved14 : REAL;
A14: =SUBSTITUTE(LEFT(Parameters!B16,IF(IFERROR(FIND("[",Parameters!B16),100)>IFERROR(FIND("(",Parameters!B16),100),IFERROR(FIND("(",Parameters!B16),100),IFERROR(FIND("[",Parameters!B16),100))-1)," ","") | C14: =IF(B14="","",_xlfn.CONCAT(B14,"_typ")) | D14: =IF(C14 = "","",_xlfn.CONCAT(C14," : STRUCT END_STRUCT;")) | E14: =IF(B14="","",_xlfn.CONCAT(B14," : ",C14,";")) | F14: =SUBSTITUTE(LEFT(Parameters!C16,IF(IFERROR(FIND("[",Parameters!C16),100)>IFERROR(FIND("(",Parameters!C16),100),IFERROR(FIND("(",Parameters!C16),100),IFERROR(FIND("[",Parameters!C16),100))-1)," ","") | H14: =IF(G14="","",_xlfn.CONCAT(G14,"_typ")) | I14: =IF(H14 = "","",_xlfn.CONCAT(H14," : STRUCT END_STRUCT;")) | J14: =IF(G14="","",_xlfn.CONCAT(G14," : ",H14,";")) | K14: =SUBSTITUTE(LEFT(Parameters!D16,IF(IFERROR(FIND("[",Parameters!D16),100)>IFERROR(FIND("(",Parameters!D16),100),IFERROR(FIND("(",Parameters!D16),100),IFERROR(FIND("[",Parameters!D16),100))-1)," ","") | L14: TMB | M14: =IF(L14="","",_xlfn.CONCAT(L14,"_typ")) -> TMB_typ | N14: =IF(M14 = "","",_xlfn.CONCAT(M14," : STRUCT END_STRUCT;")) -> TMB_typ : STRUCT END_STRUCT; | O14: =IF(L14="","",_xlfn.CONCAT(L14," : ",M14,";")) -> TMB : TMB_typ; | P14: =K14 | Q14: =Parameters!E16 -> 54 | R14: =Parameters!F16 -> MSSFlagReserved4 | S14: =IF(R14 = "","",_xlfn.CONCAT(R14," : REAL;")) -> MSSFlagReserved4 : REAL; | U14: SystemReserved15 | V14: =IF(U14 = "","",_xlfn.CONCAT(U14," : REAL;")) -> SystemReserved15 : REAL;
A15: =SUBSTITUTE(LEFT(Parameters!B17,IF(IFERROR(FIND("[",Parameters!B17),100)>IFERROR(FIND("(",Parameters!B17),100),IFERROR(FIND("(",Parameters!B17),100),IFERROR(FIND("[",Parameters!B17),100))-1)," ","") | C15: =IF(B15="","",_xlfn.CONCAT(B15,"_typ")) | D15: =IF(C15 = "","",_xlfn.CONCAT(C15," : STRUCT END_STRUCT;")) | E15: =IF(B15="","",_xlfn.CONCAT(B15," : ",C15,";")) | F15: =SUBSTITUTE(LEFT(Parameters!C17,IF(IFERROR(FIND("[",Parameters!C17),100)>IFERROR(FIND("(",Parameters!C17),100),IFERROR(FIND("(",Parameters!C17),100),IFERROR(FIND("[",Parameters!C17),100))-1)," ","") | H15: =IF(G15="","",_xlfn.CONCAT(G15,"_typ")) | I15: =IF(H15 = "","",_xlfn.CONCAT(H15," : STRUCT END_STRUCT;")) | J15: =IF(G15="","",_xlfn.CONCAT(G15," : ",H15,";")) | K15: =SUBSTITUTE(LEFT(Parameters!D17,IF(IFERROR(FIND("[",Parameters!D17),100)>IFERROR(FIND("(",Parameters!D17),100),IFERROR(FIND("(",Parameters!D17),100),IFERROR(FIND("[",Parameters!D17),100))-1)," ","") -> LoadChangeFlag | L15: Disengage | M15: =IF(L15="","",_xlfn.CONCAT(L15,"_typ")) -> Disengage_typ | N15: =IF(M15 = "","",_xlfn.CONCAT(M15," : STRUCT END_STRUCT;")) -> Disengage_typ : STRUCT END_STRUCT; | O15: =IF(L15="","",_xlfn.CONCAT(L15," : ",M15,";")) -> Disengage : Disengage_typ; | P15: =K15 -> LoadChangeFlag | Q15: =Parameters!E17 -> 55 | R15: =Parameters!F17 -> MovAvgPeriod | S15: =IF(R15 = "","",_xlfn.CONCAT(R15," : REAL;")) -> MovAvgPeriod : REAL; | U15: SystemReserved16 | V15: =IF(U15 = "","",_xlfn.CONCAT(U15," : REAL;")) -> SystemReserved16 : REAL;
A16: =SUBSTITUTE(LEFT(Parameters!B18,IF(IFERROR(FIND("[",Parameters!B18),100)>IFERROR(FIND("(",Parameters!B18),100),IFERROR(FIND("(",Parameters!B18),100),IFERROR(FIND("[",Parameters!B18),100))-1)," ","") | C16: =IF(B16="","",_xlfn.CONCAT(B16,"_typ")) | D16: =IF(C16 = "","",_xlfn.CONCAT(C16," : STRUCT END_STRUCT;")) | E16: =IF(B16="","",_xlfn.CONCAT(B16," : ",C16,";")) | F16: =SUBSTITUTE(LEFT(Parameters!C18,IF(IFERROR(FIND("[",Parameters!C18),100)>IFERROR(FIND("(",Parameters!C18),100),IFERROR(FIND("(",Parameters!C18),100),IFERROR(FIND("[",Parameters!C18),100))-1)," ","") | H16: =IF(G16="","",_xlfn.CONCAT(G16,"_typ")) | I16: =IF(H16 = "","",_xlfn.CONCAT(H16," : STRUCT END_STRUCT;")) | J16: =IF(G16="","",_xlfn.CONCAT(G16," : ",H16,";")) | K16: =SUBSTITUTE(LEFT(Parameters!D18,IF(IFERROR(FIND("[",Parameters!D18),100)>IFERROR(FIND("(",Parameters!D18),100),IFERROR(FIND("(",Parameters!D18),100),IFERROR(FIND("[",Parameters!D18),100))-1)," ","") | L16: Airventing | M16: =IF(L16="","",_xlfn.CONCAT(L16,"_typ")) -> Airventing_typ | N16: =IF(M16 = "","",_xlfn.CONCAT(M16," : STRUCT END_STRUCT;")) -> Airventing_typ : STRUCT END_STRUCT; | O16: =IF(L16="","",_xlfn.CONCAT(L16," : ",M16,";")) -> Airventing : Airventing_typ; | P16: =K16 | Q16: =Parameters!E18 -> 56 | R16: =Parameters!F18 -> ComparePoint | S16: =IF(R16 = "","",_xlfn.CONCAT(R16," : REAL;")) -> ComparePoint : REAL; | U16: SystemReserved17 | V16: =IF(U16 = "","",_xlfn.CONCAT(U16," : REAL;")) -> SystemReserved17 : REAL;
A17: =SUBSTITUTE(LEFT(Parameters!B19,IF(IFERROR(FIND("[",Parameters!B19),100)>IFERROR(FIND("(",Parameters!B19),100),IFERROR(FIND("(",Parameters!B19),100),IFERROR(FIND("[",Parameters!B19),100))-1)," ","") | C17: =IF(B17="","",_xlfn.CONCAT(B17,"_typ")) | D17: =IF(C17 = "","",_xlfn.CONCAT(C17," : STRUCT END_STRUCT;")) | E17: =IF(B17="","",_xlfn.CONCAT(B17," : ",C17,";")) | F17: =SUBSTITUTE(LEFT(Parameters!C19,IF(IFERROR(FIND("[",Parameters!C19),100)>IFERROR(FIND("(",Parameters!C19),100),IFERROR(FIND("(",Parameters!C19),100),IFERROR(FIND("[",Parameters!C19),100))-1)," ","") | H17: =IF(G17="","",_xlfn.CONCAT(G17,"_typ")) | I17: =IF(H17 = "","",_xlfn.CONCAT(H17," : STRUCT END_STRUCT;")) | J17: =IF(G17="","",_xlfn.CONCAT(G17," : ",H17,";")) | K17: =SUBSTITUTE(LEFT(Parameters!D19,IF(IFERROR(FIND("[",Parameters!D19),100)>IFERROR(FIND("(",Parameters!D19),100),IFERROR(FIND("(",Parameters!D19),100),IFERROR(FIND("[",Parameters!D19),100))-1)," ","") | L17: MOCSshutdown | M17: =IF(L17="","",_xlfn.CONCAT(L17,"_typ")) -> MOCSshutdown_typ | N17: =IF(M17 = "","",_xlfn.CONCAT(M17," : STRUCT END_STRUCT;")) -> MOCSshutdown_typ : STRUCT END_STRUCT; | O17: =IF(L17="","",_xlfn.CONCAT(L17," : ",M17,";")) -> MOCSshutdown : MOCSshutdown_typ; | P17: =K17 | Q17: =Parameters!E19 -> 57 | R17: =Parameters!F19 -> LoadChangeThreshold | S17: =IF(R17 = "","",_xlfn.CONCAT(R17," : REAL;")) -> LoadChangeThreshold : REAL; | U17: SystemReserved18 | V17: =IF(U17 = "","",_xlfn.CONCAT(U17," : REAL;")) -> SystemReserved18 : REAL;
A18: =SUBSTITUTE(LEFT(Parameters!B20,IF(IFERROR(FIND("[",Parameters!B20),100)>IFERROR(FIND("(",Parameters!B20),100),IFERROR(FIND("(",Parameters!B20),100),IFERROR(FIND("[",Parameters!B20),100))-1)," ","") | C18: =IF(B18="","",_xlfn.CONCAT(B18,"_typ")) | D18: =IF(C18 = "","",_xlfn.CONCAT(C18," : STRUCT END_STRUCT;")) | E18: =IF(B18="","",_xlfn.CONCAT(B18," : ",C18,";")) | F18: =SUBSTITUTE(LEFT(Parameters!C20,IF(IFERROR(FIND("[",Parameters!C20),100)>IFERROR(FIND("(",Parameters!C20),100),IFERROR(FIND("(",Parameters!C20),100),IFERROR(FIND("[",Parameters!C20),100))-1)," ","") | H18: =IF(G18="","",_xlfn.CONCAT(G18,"_typ")) | I18: =IF(H18 = "","",_xlfn.CONCAT(H18," : STRUCT END_STRUCT;")) | J18: =IF(G18="","",_xlfn.CONCAT(G18," : ",H18,";")) | K18: =SUBSTITUTE(LEFT(Parameters!D20,IF(IFERROR(FIND("[",Parameters!D20),100)>IFERROR(FIND("(",Parameters!D20),100),IFERROR(FIND("(",Parameters!D20),100),IFERROR(FIND("[",Parameters!D20),100))-1)," ","") | L18: Valveshutdown | M18: =IF(L18="","",_xlfn.CONCAT(L18,"_typ")) -> Valveshutdown_typ | N18: =IF(M18 = "","",_xlfn.CONCAT(M18," : STRUCT END_STRUCT;")) -> Valveshutdown_typ : STRUCT END_STRUCT; | O18: =IF(L18="","",_xlfn.CONCAT(L18," : ",M18,";")) -> Valveshutdown : Valveshutdown_typ; | P18: =K18 | Q18: =Parameters!E20 -> 58 | R18: =Parameters!F20 -> LoadCangeFlagFallingDelay | S18: =IF(R18 = "","",_xlfn.CONCAT(R18," : REAL;")) -> LoadCangeFlagFallingDelay : REAL; | U18: SystemReserved19 | V18: =IF(U18 = "","",_xlfn.CONCAT(U18," : REAL;")) -> SystemReserved19 : REAL;
A19: =SUBSTITUTE(LEFT(Parameters!B21,IF(IFERROR(FIND("[",Parameters!B21),100)>IFERROR(FIND("(",Parameters!B21),100),IFERROR(FIND("(",Parameters!B21),100),IFERROR(FIND("[",Parameters!B21),100))-1)," ","") | C19: =IF(B19="","",_xlfn.CONCAT(B19,"_typ")) | D19: =IF(C19 = "","",_xlfn.CONCAT(C19," : STRUCT END_STRUCT;")) | E19: =IF(B19="","",_xlfn.CONCAT(B19," : ",C19,";")) | F19: =SUBSTITUTE(LEFT(Parameters!C21,IF(IFERROR(FIND("[",Parameters!C21),100)>IFERROR(FIND("(",Parameters!C21),100),IFERROR(FIND("(",Parameters!C21),100),IFERROR(FIND("[",Parameters!C21),100))-1)," ","") | H19: =IF(G19="","",_xlfn.CONCAT(G19,"_typ")) | I19: =IF(H19 = "","",_xlfn.CONCAT(H19," : STRUCT END_STRUCT;")) | J19: =IF(G19="","",_xlfn.CONCAT(G19," : ",H19,";")) | K19: =SUBSTITUTE(LEFT(Parameters!D21,IF(IFERROR(FIND("[",Parameters!D21),100)>IFERROR(FIND("(",Parameters!D21),100),IFERROR(FIND("(",Parameters!D21),100),IFERROR(FIND("[",Parameters!D21),100))-1)," ","") | L19: FODSInitReady | M19: =IF(L19="","",_xlfn.CONCAT(L19,"_typ")) -> FODSInitReady_typ | N19: =IF(M19 = "","",_xlfn.CONCAT(M19," : STRUCT END_STRUCT;")) -> FODSInitReady_typ : STRUCT END_STRUCT; | O19: =IF(L19="","",_xlfn.CONCAT(L19," : ",M19,";")) -> FODSInitReady : FODSInitReady_typ; | P19: =K19 | Q19: =Parameters!E21 -> 59 | R19: =Parameters!F21 -> LoadCangeFlagReserved4 | S19: =IF(R19 = "","",_xlfn.CONCAT(R19," : REAL;")) -> LoadCangeFlagReserved4 : REAL; | U19: SystemReserved20 | V19: =IF(U19 = "","",_xlfn.CONCAT(U19," : REAL;")) -> SystemReserved20 : REAL;
A20: =SUBSTITUTE(LEFT(Parameters!B22,IF(IFERROR(FIND("[",Parameters!B22),100)>IFERROR(FIND("(",Parameters!B22),100),IFERROR(FIND("(",Parameters!B22),100),IFERROR(FIND("[",Parameters!B22),100))-1)," ","") | C20: =IF(B20="","",_xlfn.CONCAT(B20,"_typ")) | D20: =IF(C20 = "","",_xlfn.CONCAT(C20," : STRUCT END_STRUCT;")) | E20: =IF(B20="","",_xlfn.CONCAT(B20," : ",C20,";")) | F20: =SUBSTITUTE(LEFT(Parameters!C22,IF(IFERROR(FIND("[",Parameters!C22),100)>IFERROR(FIND("(",Parameters!C22),100),IFERROR(FIND("(",Parameters!C22),100),IFERROR(FIND("[",Parameters!C22),100))-1)," ","") | H20: =IF(G20="","",_xlfn.CONCAT(G20,"_typ")) | I20: =IF(H20 = "","",_xlfn.CONCAT(H20," : STRUCT END_STRUCT;")) | J20: =IF(G20="","",_xlfn.CONCAT(G20," : ",H20,";")) | K20: =SUBSTITUTE(LEFT(Parameters!D22,IF(IFERROR(FIND("[",Parameters!D22),100)>IFERROR(FIND("(",Parameters!D22),100),IFERROR(FIND("(",Parameters!D22),100),IFERROR(FIND("[",Parameters!D22),100))-1)," ","") -> SystemWarmedUpFlag | L20: FODSCooling | M20: =IF(L20="","",_xlfn.CONCAT(L20,"_typ")) -> FODSCooling_typ | N20: =IF(M20 = "","",_xlfn.CONCAT(M20," : STRUCT END_STRUCT;")) -> FODSCooling_typ : STRUCT END_STRUCT; | O20: =IF(L20="","",_xlfn.CONCAT(L20," : ",M20,";")) -> FODSCooling : FODSCooling_typ; | P20: =K20 -> SystemWarmedUpFlag | Q20: =Parameters!E22 -> 60 | R20: =Parameters!F22 -> WarmUpDTemp | S20: =IF(R20 = "","",_xlfn.CONCAT(R20," : REAL;")) -> WarmUpDTemp : REAL; | U20: SystemReserved21 | V20: =IF(U20 = "","",_xlfn.CONCAT(U20," : REAL;")) -> SystemReserved21 : REAL;
A21: =SUBSTITUTE(LEFT(Parameters!B23,IF(IFERROR(FIND("[",Parameters!B23),100)>IFERROR(FIND("(",Parameters!B23),100),IFERROR(FIND("(",Parameters!B23),100),IFERROR(FIND("[",Parameters!B23),100))-1)," ","") | C21: =IF(B21="","",_xlfn.CONCAT(B21,"_typ")) | D21: =IF(C21 = "","",_xlfn.CONCAT(C21," : STRUCT END_STRUCT;")) | E21: =IF(B21="","",_xlfn.CONCAT(B21," : ",C21,";")) | F21: =SUBSTITUTE(LEFT(Parameters!C23,IF(IFERROR(FIND("[",Parameters!C23),100)>IFERROR(FIND("(",Parameters!C23),100),IFERROR(FIND("(",Parameters!C23),100),IFERROR(FIND("[",Parameters!C23),100))-1)," ","") | H21: =IF(G21="","",_xlfn.CONCAT(G21,"_typ")) | I21: =IF(H21 = "","",_xlfn.CONCAT(H21," : STRUCT END_STRUCT;")) | J21: =IF(G21="","",_xlfn.CONCAT(G21," : ",H21,";")) | K21: =SUBSTITUTE(LEFT(Parameters!D23,IF(IFERROR(FIND("[",Parameters!D23),100)>IFERROR(FIND("(",Parameters!D23),100),IFERROR(FIND("(",Parameters!D23),100),IFERROR(FIND("[",Parameters!D23),100))-1)," ","") | L21: FODSDosing | M21: =IF(L21="","",_xlfn.CONCAT(L21,"_typ")) -> FODSDosing_typ | N21: =IF(M21 = "","",_xlfn.CONCAT(M21," : STRUCT END_STRUCT;")) -> FODSDosing_typ : STRUCT END_STRUCT; | O21: =IF(L21="","",_xlfn.CONCAT(L21," : ",M21,";")) -> FODSDosing : FODSDosing_typ; | P21: =K21 | Q21: =Parameters!E23 -> 61 | R21: =Parameters!F23 -> WarmUpITemp | S21: =IF(R21 = "","",_xlfn.CONCAT(R21," : REAL;")) -> WarmUpITemp : REAL; | U21: SystemReserved22 | V21: =IF(U21 = "","",_xlfn.CONCAT(U21," : REAL;")) -> SystemReserved22 : REAL;
A22: =SUBSTITUTE(LEFT(Parameters!B24,IF(IFERROR(FIND("[",Parameters!B24),100)>IFERROR(FIND("(",Parameters!B24),100),IFERROR(FIND("(",Parameters!B24),100),IFERROR(FIND("[",Parameters!B24),100))-1)," ","") | C22: =IF(B22="","",_xlfn.CONCAT(B22,"_typ")) | D22: =IF(C22 = "","",_xlfn.CONCAT(C22," : STRUCT END_STRUCT;")) | E22: =IF(B22="","",_xlfn.CONCAT(B22," : ",C22,";")) | F22: =SUBSTITUTE(LEFT(Parameters!C24,IF(IFERROR(FIND("[",Parameters!C24),100)>IFERROR(FIND("(",Parameters!C24),100),IFERROR(FIND("(",Parameters!C24),100),IFERROR(FIND("[",Parameters!C24),100))-1)," ","") | H22: =IF(G22="","",_xlfn.CONCAT(G22,"_typ")) | I22: =IF(H22 = "","",_xlfn.CONCAT(H22," : STRUCT END_STRUCT;")) | J22: =IF(G22="","",_xlfn.CONCAT(G22," : ",H22,";")) | K22: =SUBSTITUTE(LEFT(Parameters!D24,IF(IFERROR(FIND("[",Parameters!D24),100)>IFERROR(FIND("(",Parameters!D24),100),IFERROR(FIND("(",Parameters!D24),100),IFERROR(FIND("[",Parameters!D24),100))-1)," ","") | L22: FODSFlushing | M22: =IF(L22="","",_xlfn.CONCAT(L22,"_typ")) -> FODSFlushing_typ | N22: =IF(M22 = "","",_xlfn.CONCAT(M22," : STRUCT END_STRUCT;")) -> FODSFlushing_typ : STRUCT END_STRUCT; | O22: =IF(L22="","",_xlfn.CONCAT(L22," : ",M22,";")) -> FODSFlushing : FODSFlushing_typ; | P22: =K22 | Q22: =Parameters!E24 -> 62 | R22: =Parameters!F24 -> WarmUpChITemp | S22: =IF(R22 = "","",_xlfn.CONCAT(R22," : REAL;")) -> WarmUpChITemp : REAL; | U22: SystemReserved23 | V22: =IF(U22 = "","",_xlfn.CONCAT(U22," : REAL;")) -> SystemReserved23 : REAL;
A23: =SUBSTITUTE(LEFT(Parameters!B25,IF(IFERROR(FIND("[",Parameters!B25),100)>IFERROR(FIND("(",Parameters!B25),100),IFERROR(FIND("(",Parameters!B25),100),IFERROR(FIND("[",Parameters!B25),100))-1)," ","") | C23: =IF(B23="","",_xlfn.CONCAT(B23,"_typ")) | D23: =IF(C23 = "","",_xlfn.CONCAT(C23," : STRUCT END_STRUCT;")) | E23: =IF(B23="","",_xlfn.CONCAT(B23," : ",C23,";")) | F23: =SUBSTITUTE(LEFT(Parameters!C25,IF(IFERROR(FIND("[",Parameters!C25),100)>IFERROR(FIND("(",Parameters!C25),100),IFERROR(FIND("(",Parameters!C25),100),IFERROR(FIND("[",Parameters!C25),100))-1)," ","") | H23: =IF(G23="","",_xlfn.CONCAT(G23,"_typ")) | I23: =IF(H23 = "","",_xlfn.CONCAT(H23," : STRUCT END_STRUCT;")) | J23: =IF(G23="","",_xlfn.CONCAT(G23," : ",H23,";")) | K23: =SUBSTITUTE(LEFT(Parameters!D25,IF(IFERROR(FIND("[",Parameters!D25),100)>IFERROR(FIND("(",Parameters!D25),100),IFERROR(FIND("(",Parameters!D25),100),IFERROR(FIND("[",Parameters!D25),100))-1)," ","") | L23: CommonReservedCat3 | M23: =IF(L23="","",_xlfn.CONCAT(L23,"_typ")) -> CommonReservedCat3_typ | N23: =IF(M23 = "","",_xlfn.CONCAT(M23," : STRUCT END_STRUCT;")) -> CommonReservedCat3_typ : STRUCT END_STRUCT; | O23: =IF(L23="","",_xlfn.CONCAT(L23," : ",M23,";")) -> CommonReservedCat3 : CommonReservedCat3_typ; | P23: =K23 | Q23: =Parameters!E25 -> 63 | R23: =Parameters!F25 -> WarmUpChMTemp | S23: =IF(R23 = "","",_xlfn.CONCAT(R23," : REAL;")) -> WarmUpChMTemp : REAL; | U23: SystemReserved24 | V23: =IF(U23 = "","",_xlfn.CONCAT(U23," : REAL;")) -> SystemReserved24 : REAL;
A24: =SUBSTITUTE(LEFT(Parameters!B26,IF(IFERROR(FIND("[",Parameters!B26),100)>IFERROR(FIND("(",Parameters!B26),100),IFERROR(FIND("(",Parameters!B26),100),IFERROR(FIND("[",Parameters!B26),100))-1)," ","") | C24: =IF(B24="","",_xlfn.CONCAT(B24,"_typ")) | D24: =IF(C24 = "","",_xlfn.CONCAT(C24," : STRUCT END_STRUCT;")) | E24: =IF(B24="","",_xlfn.CONCAT(B24," : ",C24,";")) | F24: =SUBSTITUTE(LEFT(Parameters!C26,IF(IFERROR(FIND("[",Parameters!C26),100)>IFERROR(FIND("(",Parameters!C26),100),IFERROR(FIND("(",Parameters!C26),100),IFERROR(FIND("[",Parameters!C26),100))-1)," ","") | H24: =IF(G24="","",_xlfn.CONCAT(G24,"_typ")) | I24: =IF(H24 = "","",_xlfn.CONCAT(H24," : STRUCT END_STRUCT;")) | J24: =IF(G24="","",_xlfn.CONCAT(G24," : ",H24,";")) | K24: =SUBSTITUTE(LEFT(Parameters!D26,IF(IFERROR(FIND("[",Parameters!D26),100)>IFERROR(FIND("(",Parameters!D26),100),IFERROR(FIND("(",Parameters!D26),100),IFERROR(FIND("[",Parameters!D26),100))-1)," ","") | L24: FFpara | M24: =IF(L24="","",_xlfn.CONCAT(L24,"_typ")) -> FFpara_typ | N24: =IF(M24 = "","",_xlfn.CONCAT(M24," : STRUCT END_STRUCT;")) -> FFpara_typ : STRUCT END_STRUCT; | O24: =IF(L24="","",_xlfn.CONCAT(L24," : ",M24,";")) -> FFpara : FFpara_typ; | P24: =K24 | Q24: =Parameters!E26 -> 64 | R24: =Parameters!F26 -> WarmUpChOTemp | S24: =IF(R24 = "","",_xlfn.CONCAT(R24," : REAL;")) -> WarmUpChOTemp : REAL; | U24: SystemReserved25 | V24: =IF(U24 = "","",_xlfn.CONCAT(U24," : REAL;")) -> SystemReserved25 : REAL;
A25: =SUBSTITUTE(LEFT(Parameters!B27,IF(IFERROR(FIND("[",Parameters!B27),100)>IFERROR(FIND("(",Parameters!B27),100),IFERROR(FIND("(",Parameters!B27),100),IFERROR(FIND("[",Parameters!B27),100))-1)," ","") | C25: =IF(B25="","",_xlfn.CONCAT(B25,"_typ")) | D25: =IF(C25 = "","",_xlfn.CONCAT(C25," : STRUCT END_STRUCT;")) | E25: =IF(B25="","",_xlfn.CONCAT(B25," : ",C25,";")) | F25: =SUBSTITUTE(LEFT(Parameters!C27,IF(IFERROR(FIND("[",Parameters!C27),100)>IFERROR(FIND("(",Parameters!C27),100),IFERROR(FIND("(",Parameters!C27),100),IFERROR(FIND("[",Parameters!C27),100))-1)," ","") | H25: =IF(G25="","",_xlfn.CONCAT(G25,"_typ")) | I25: =IF(H25 = "","",_xlfn.CONCAT(H25," : STRUCT END_STRUCT;")) | J25: =IF(G25="","",_xlfn.CONCAT(G25," : ",H25,";")) | K25: =SUBSTITUTE(LEFT(Parameters!D27,IF(IFERROR(FIND("[",Parameters!D27),100)>IFERROR(FIND("(",Parameters!D27),100),IFERROR(FIND("(",Parameters!D27),100),IFERROR(FIND("[",Parameters!D27),100))-1)," ","") -> FlagReserved | L25: EngineLoad | M25: =IF(L25="","",_xlfn.CONCAT(L25,"_typ")) -> EngineLoad_typ | N25: =IF(M25 = "","",_xlfn.CONCAT(M25," : STRUCT END_STRUCT;")) -> EngineLoad_typ : STRUCT END_STRUCT; | O25: =IF(L25="","",_xlfn.CONCAT(L25," : ",M25,";")) -> EngineLoad : EngineLoad_typ; | P25: =K25 -> FlagReserved | Q25: =Parameters!E27 -> 65 | R25: =Parameters!F27 -> FlagReserved15 | S25: =IF(R25 = "","",_xlfn.CONCAT(R25," : REAL;")) -> FlagReserved15 : REAL; | U25: SystemReserved26 | V25: =IF(U25 = "","",_xlfn.CONCAT(U25," : REAL;")) -> SystemReserved26 : REAL; | W25: FlagReserved15 | X25: =IF(W25 = "","",_xlfn.CONCAT(W25," : REAL;")) -> FlagReserved15 : REAL;
A26: =SUBSTITUTE(LEFT(Parameters!B28,IF(IFERROR(FIND("[",Parameters!B28),100)>IFERROR(FIND("(",Parameters!B28),100),IFERROR(FIND("(",Parameters!B28),100),IFERROR(FIND("[",Parameters!B28),100))-1)," ","") | C26: =IF(B26="","",_xlfn.CONCAT(B26,"_typ")) | D26: =IF(C26 = "","",_xlfn.CONCAT(C26," : STRUCT END_STRUCT;")) | E26: =IF(B26="","",_xlfn.CONCAT(B26," : ",C26,";")) | F26: =SUBSTITUTE(LEFT(Parameters!C28,IF(IFERROR(FIND("[",Parameters!C28),100)>IFERROR(FIND("(",Parameters!C28),100),IFERROR(FIND("(",Parameters!C28),100),IFERROR(FIND("[",Parameters!C28),100))-1)," ","") | H26: =IF(G26="","",_xlfn.CONCAT(G26,"_typ")) | I26: =IF(H26 = "","",_xlfn.CONCAT(H26," : STRUCT END_STRUCT;")) | J26: =IF(G26="","",_xlfn.CONCAT(G26," : ",H26,";")) | K26: =SUBSTITUTE(LEFT(Parameters!D28,IF(IFERROR(FIND("[",Parameters!D28),100)>IFERROR(FIND("(",Parameters!D28),100),IFERROR(FIND("(",Parameters!D28),100),IFERROR(FIND("[",Parameters!D28),100))-1)," ","") | L26: ExhFlowrate | M26: =IF(L26="","",_xlfn.CONCAT(L26,"_typ")) -> ExhFlowrate_typ | N26: =IF(M26 = "","",_xlfn.CONCAT(M26," : STRUCT END_STRUCT;")) -> ExhFlowrate_typ : STRUCT END_STRUCT; | O26: =IF(L26="","",_xlfn.CONCAT(L26," : ",M26,";")) -> ExhFlowrate : ExhFlowrate_typ; | P26: =K26 | Q26: =Parameters!E28 -> ... | R26: =Parameters!F28 -> ... | S26: =IF(R26 = "","",_xlfn.CONCAT(R26," : REAL;")) -> ... : REAL; | U26: SystemReserved27 | V26: =IF(U26 = "","",_xlfn.CONCAT(U26," : REAL;")) -> SystemReserved27 : REAL; | W26: FlagReserved16 | X26: =IF(W26 = "","",_xlfn.CONCAT(W26," : REAL;")) -> FlagReserved16 : REAL;
A27: =SUBSTITUTE(LEFT(Parameters!B29,IF(IFERROR(FIND("[",Parameters!B29),100)>IFERROR(FIND("(",Parameters!B29),100),IFERROR(FIND("(",Parameters!B29),100),IFERROR(FIND("[",Parameters!B29),100))-1)," ","") | C27: =IF(B27="","",_xlfn.CONCAT(B27,"_typ")) | D27: =IF(C27 = "","",_xlfn.CONCAT(C27," : STRUCT END_STRUCT;")) | E27: =IF(B27="","",_xlfn.CONCAT(B27," : ",C27,";")) | F27: =SUBSTITUTE(LEFT(Parameters!C29,IF(IFERROR(FIND("[",Parameters!C29),100)>IFERROR(FIND("(",Parameters!C29),100),IFERROR(FIND("(",Parameters!C29),100),IFERROR(FIND("[",Parameters!C29),100))-1)," ","") | H27: =IF(G27="","",_xlfn.CONCAT(G27,"_typ")) | I27: =IF(H27 = "","",_xlfn.CONCAT(H27," : STRUCT END_STRUCT;")) | J27: =IF(G27="","",_xlfn.CONCAT(G27," : ",H27,";")) | K27: =SUBSTITUTE(LEFT(Parameters!D29,IF(IFERROR(FIND("[",Parameters!D29),100)>IFERROR(FIND("(",Parameters!D29),100),IFERROR(FIND("(",Parameters!D29),100),IFERROR(FIND("[",Parameters!D29),100))-1)," ","") | L27: HUInletRefTemp | M27: =IF(L27="","",_xlfn.CONCAT(L27,"_typ")) -> HUInletRefTemp_typ | N27: =IF(M27 = "","",_xlfn.CONCAT(M27," : STRUCT END_STRUCT;")) -> HUInletRefTemp_typ : STRUCT END_STRUCT; | O27: =IF(L27="","",_xlfn.CONCAT(L27," : ",M27,";")) -> HUInletRefTemp : HUInletRefTemp_typ; | P27: =K27 | Q27: =Parameters!E29 -> 99 | R27: =Parameters!F29 -> FlagReserved49 | S27: =IF(R27 = "","",_xlfn.CONCAT(R27," : REAL;")) -> FlagReserved49 : REAL; | U27: SystemReserved28 | V27: =IF(U27 = "","",_xlfn.CONCAT(U27," : REAL;")) -> SystemReserved28 : REAL; | W27: FlagReserved17 | X27: =IF(W27 = "","",_xlfn.CONCAT(W27," : REAL;")) -> FlagReserved17 : REAL;
A28: =SUBSTITUTE(LEFT(Parameters!B30,IF(IFERROR(FIND("[",Parameters!B30),100)>IFERROR(FIND("(",Parameters!B30),100),IFERROR(FIND("(",Parameters!B30),100),IFERROR(FIND("[",Parameters!B30),100))-1)," ","") | C28: =IF(B28="","",_xlfn.CONCAT(B28,"_typ")) | D28: =IF(C28 = "","",_xlfn.CONCAT(C28," : STRUCT END_STRUCT;")) | E28: =IF(B28="","",_xlfn.CONCAT(B28," : ",C28,";")) | F28: =SUBSTITUTE(LEFT(Parameters!C30,IF(IFERROR(FIND("[",Parameters!C30),100)>IFERROR(FIND("(",Parameters!C30),100),IFERROR(FIND("(",Parameters!C30),100),IFERROR(FIND("[",Parameters!C30),100))-1)," ","") -> Main | H28: =IF(G28="","",_xlfn.CONCAT(G28,"_typ")) | I28: =IF(H28 = "","",_xlfn.CONCAT(H28," : STRUCT END_STRUCT;")) | J28: =IF(G28="","",_xlfn.CONCAT(G28," : ",H28,";")) | K28: =SUBSTITUTE(LEFT(Parameters!D30,IF(IFERROR(FIND("[",Parameters!D30),100)>IFERROR(FIND("(",Parameters!D30),100),IFERROR(FIND("(",Parameters!D30),100),IFERROR(FIND("[",Parameters!D30),100))-1)," ","") -> Init | L28: CorrectionFactor | M28: =IF(L28="","",_xlfn.CONCAT(L28,"_typ")) -> CorrectionFactor_typ | N28: =IF(M28 = "","",_xlfn.CONCAT(M28," : STRUCT END_STRUCT;")) -> CorrectionFactor_typ : STRUCT END_STRUCT; | O28: =IF(L28="","",_xlfn.CONCAT(L28," : ",M28,";")) -> CorrectionFactor : CorrectionFactor_typ; | P28: =K28 -> Init | Q28: =Parameters!E30 -> 100 | R28: =Parameters!F30 -> InitReserved0 | S28: =IF(R28 = "","",_xlfn.CONCAT(R28," : REAL;")) -> InitReserved0 : REAL; | U28: SystemReserved29 | V28: =IF(U28 = "","",_xlfn.CONCAT(U28," : REAL;")) -> SystemReserved29 : REAL; | W28: FlagReserved18 | X28: =IF(W28 = "","",_xlfn.CONCAT(W28," : REAL;")) -> FlagReserved18 : REAL;
A29: =SUBSTITUTE(LEFT(Parameters!B31,IF(IFERROR(FIND("[",Parameters!B31),100)>IFERROR(FIND("(",Parameters!B31),100),IFERROR(FIND("(",Parameters!B31),100),IFERROR(FIND("[",Parameters!B31),100))-1)," ","") | C29: =IF(B29="","",_xlfn.CONCAT(B29,"_typ")) | D29: =IF(C29 = "","",_xlfn.CONCAT(C29," : STRUCT END_STRUCT;")) | E29: =IF(B29="","",_xlfn.CONCAT(B29," : ",C29,";")) | F29: =SUBSTITUTE(LEFT(Parameters!C31,IF(IFERROR(FIND("[",Parameters!C31),100)>IFERROR(FIND("(",Parameters!C31),100),IFERROR(FIND("(",Parameters!C31),100),IFERROR(FIND("[",Parameters!C31),100))-1)," ","") | H29: =IF(G29="","",_xlfn.CONCAT(G29,"_typ")) | I29: =IF(H29 = "","",_xlfn.CONCAT(H29," : STRUCT END_STRUCT;")) | J29: =IF(G29="","",_xlfn.CONCAT(G29," : ",H29,";")) | K29: =SUBSTITUTE(LEFT(Parameters!D31,IF(IFERROR(FIND("[",Parameters!D31),100)>IFERROR(FIND("(",Parameters!D31),100),IFERROR(FIND("(",Parameters!D31),100),IFERROR(FIND("[",Parameters!D31),100))-1)," ","") | L29: MOCSTempPgain | M29: =IF(L29="","",_xlfn.CONCAT(L29,"_typ")) -> MOCSTempPgain_typ | N29: =IF(M29 = "","",_xlfn.CONCAT(M29," : STRUCT END_STRUCT;")) -> MOCSTempPgain_typ : STRUCT END_STRUCT; | O29: =IF(L29="","",_xlfn.CONCAT(L29," : ",M29,";")) -> MOCSTempPgain : MOCSTempPgain_typ; | P29: =K29 | Q29: =Parameters!E31 -> 101 | R29: =Parameters!F31 -> InitReserved1 | S29: =IF(R29 = "","",_xlfn.CONCAT(R29," : REAL;")) -> InitReserved1 : REAL; | U29: SystemReserved30 | V29: =IF(U29 = "","",_xlfn.CONCAT(U29," : REAL;")) -> SystemReserved30 : REAL; | W29: FlagReserved19 | X29: =IF(W29 = "","",_xlfn.CONCAT(W29," : REAL;")) -> FlagReserved19 : REAL;
A30: =SUBSTITUTE(LEFT(Parameters!B32,IF(IFERROR(FIND("[",Parameters!B32),100)>IFERROR(FIND("(",Parameters!B32),100),IFERROR(FIND("(",Parameters!B32),100),IFERROR(FIND("[",Parameters!B32),100))-1)," ","") | C30: =IF(B30="","",_xlfn.CONCAT(B30,"_typ")) | D30: =IF(C30 = "","",_xlfn.CONCAT(C30," : STRUCT END_STRUCT;")) | E30: =IF(B30="","",_xlfn.CONCAT(B30," : ",C30,";")) | F30: =SUBSTITUTE(LEFT(Parameters!C32,IF(IFERROR(FIND("[",Parameters!C32),100)>IFERROR(FIND("(",Parameters!C32),100),IFERROR(FIND("(",Parameters!C32),100),IFERROR(FIND("[",Parameters!C32),100))-1)," ","") | H30: =IF(G30="","",_xlfn.CONCAT(G30,"_typ")) | I30: =IF(H30 = "","",_xlfn.CONCAT(H30," : STRUCT END_STRUCT;")) | J30: =IF(G30="","",_xlfn.CONCAT(G30," : ",H30,";")) | K30: =SUBSTITUTE(LEFT(Parameters!D32,IF(IFERROR(FIND("[",Parameters!D32),100)>IFERROR(FIND("(",Parameters!D32),100),IFERROR(FIND("(",Parameters!D32),100),IFERROR(FIND("[",Parameters!D32),100))-1)," ","") | L30: APIDgain | M30: =IF(L30="","",_xlfn.CONCAT(L30,"_typ")) -> APIDgain_typ | N30: =IF(M30 = "","",_xlfn.CONCAT(M30," : STRUCT END_STRUCT;")) -> APIDgain_typ : STRUCT END_STRUCT; | O30: =IF(L30="","",_xlfn.CONCAT(L30," : ",M30,";")) -> APIDgain : APIDgain_typ; | P30: =K30 | Q30: =Parameters!E32 -> 102 | R30: =Parameters!F32 -> InitReserved2 | S30: =IF(R30 = "","",_xlfn.CONCAT(R30," : REAL;")) -> InitReserved2 : REAL; | U30: SystemReserved31 | V30: =IF(U30 = "","",_xlfn.CONCAT(U30," : REAL;")) -> SystemReserved31 : REAL; | W30: FlagReserved20 | X30: =IF(W30 = "","",_xlfn.CONCAT(W30," : REAL;")) -> FlagReserved20 : REAL;
A31: =SUBSTITUTE(LEFT(Parameters!B33,IF(IFERROR(FIND("[",Parameters!B33),100)>IFERROR(FIND("(",Parameters!B33),100),IFERROR(FIND("(",Parameters!B33),100),IFERROR(FIND("[",Parameters!B33),100))-1)," ","") | C31: =IF(B31="","",_xlfn.CONCAT(B31,"_typ")) | D31: =IF(C31 = "","",_xlfn.CONCAT(C31," : STRUCT END_STRUCT;")) | E31: =IF(B31="","",_xlfn.CONCAT(B31," : ",C31,";")) | F31: =SUBSTITUTE(LEFT(Parameters!C33,IF(IFERROR(FIND("[",Parameters!C33),100)>IFERROR(FIND("(",Parameters!C33),100),IFERROR(FIND("(",Parameters!C33),100),IFERROR(FIND("[",Parameters!C33),100))-1)," ","") | H31: =IF(G31="","",_xlfn.CONCAT(G31,"_typ")) | I31: =IF(H31 = "","",_xlfn.CONCAT(H31," : STRUCT END_STRUCT;")) | J31: =IF(G31="","",_xlfn.CONCAT(G31," : ",H31,";")) | K31: =SUBSTITUTE(LEFT(Parameters!D33,IF(IFERROR(FIND("[",Parameters!D33),100)>IFERROR(FIND("(",Parameters!D33),100),IFERROR(FIND("(",Parameters!D33),100),IFERROR(FIND("[",Parameters!D33),100))-1)," ","") | L31: IndivReservedCat3 | M31: =IF(L31="","",_xlfn.CONCAT(L31,"_typ")) -> IndivReservedCat3 _typ | N31: =IF(M31 = "","",_xlfn.CONCAT(M31," : STRUCT END_STRUCT;")) -> IndivReservedCat3 _typ : STRUCT END_STRUCT; | O31: =IF(L31="","",_xlfn.CONCAT(L31," : ",M31,";")) -> IndivReservedCat3 : IndivReservedCat3 _typ; | P31: =K31 | Q31: =Parameters!E33 -> 103 | R31: =Parameters!F33 -> InitReserved3 | S31: =IF(R31 = "","",_xlfn.CONCAT(R31," : REAL;")) -> InitReserved3 : REAL; | U31: SystemReserved32 | V31: =IF(U31 = "","",_xlfn.CONCAT(U31," : REAL;")) -> SystemReserved32 : REAL; | W31: FlagReserved21 | X31: =IF(W31 = "","",_xlfn.CONCAT(W31," : REAL;")) -> FlagReserved21 : REAL;
A32: =SUBSTITUTE(LEFT(Parameters!B34,IF(IFERROR(FIND("[",Parameters!B34),100)>IFERROR(FIND("(",Parameters!B34),100),IFERROR(FIND("(",Parameters!B34),100),IFERROR(FIND("[",Parameters!B34),100))-1)," ","") | C32: =IF(B32="","",_xlfn.CONCAT(B32,"_typ")) | D32: =IF(C32 = "","",_xlfn.CONCAT(C32," : STRUCT END_STRUCT;")) | E32: =IF(B32="","",_xlfn.CONCAT(B32," : ",C32,";")) | F32: =SUBSTITUTE(LEFT(Parameters!C34,IF(IFERROR(FIND("[",Parameters!C34),100)>IFERROR(FIND("(",Parameters!C34),100),IFERROR(FIND("(",Parameters!C34),100),IFERROR(FIND("[",Parameters!C34),100))-1)," ","") | H32: =IF(G32="","",_xlfn.CONCAT(G32,"_typ")) | I32: =IF(H32 = "","",_xlfn.CONCAT(H32," : STRUCT END_STRUCT;")) | J32: =IF(G32="","",_xlfn.CONCAT(G32," : ",H32,";")) | K32: =SUBSTITUTE(LEFT(Parameters!D34,IF(IFERROR(FIND("[",Parameters!D34),100)>IFERROR(FIND("(",Parameters!D34),100),IFERROR(FIND("(",Parameters!D34),100),IFERROR(FIND("[",Parameters!D34),100))-1)," ","") | M32: =IF(L32="","",_xlfn.CONCAT(L32,"_typ")) | N32: =IF(M32 = "","",_xlfn.CONCAT(M32," : STRUCT END_STRUCT;")) | O32: =IF(L32="","",_xlfn.CONCAT(L32," : ",M32,";")) | P32: =K32 | Q32: =Parameters!E34 -> 104 | R32: =Parameters!F34 -> InitReserved4 | S32: =IF(R32 = "","",_xlfn.CONCAT(R32," : REAL;")) -> InitReserved4 : REAL; | U32: SystemReserved33 | V32: =IF(U32 = "","",_xlfn.CONCAT(U32," : REAL;")) -> SystemReserved33 : REAL; | W32: FlagReserved22 | X32: =IF(W32 = "","",_xlfn.CONCAT(W32," : REAL;")) -> FlagReserved22 : REAL;
A33: =SUBSTITUTE(LEFT(Parameters!B35,IF(IFERROR(FIND("[",Parameters!B35),100)>IFERROR(FIND("(",Parameters!B35),100),IFERROR(FIND("(",Parameters!B35),100),IFERROR(FIND("[",Parameters!B35),100))-1)," ","") | C33: =IF(B33="","",_xlfn.CONCAT(B33,"_typ")) | D33: =IF(C33 = "","",_xlfn.CONCAT(C33," : STRUCT END_STRUCT;")) | E33: =IF(B33="","",_xlfn.CONCAT(B33," : ",C33,";")) | F33: =SUBSTITUTE(LEFT(Parameters!C35,IF(IFERROR(FIND("[",Parameters!C35),100)>IFERROR(FIND("(",Parameters!C35),100),IFERROR(FIND("(",Parameters!C35),100),IFERROR(FIND("[",Parameters!C35),100))-1)," ","") | H33: =IF(G33="","",_xlfn.CONCAT(G33,"_typ")) | I33: =IF(H33 = "","",_xlfn.CONCAT(H33," : STRUCT END_STRUCT;")) | J33: =IF(G33="","",_xlfn.CONCAT(G33," : ",H33,";")) | K33: =SUBSTITUTE(LEFT(Parameters!D35,IF(IFERROR(FIND("[",Parameters!D35),100)>IFERROR(FIND("(",Parameters!D35),100),IFERROR(FIND("(",Parameters!D35),100),IFERROR(FIND("[",Parameters!D35),100))-1)," ","") -> Sealing | M33: =IF(L33="","",_xlfn.CONCAT(L33,"_typ")) | N33: =IF(M33 = "","",_xlfn.CONCAT(M33," : STRUCT END_STRUCT;")) | O33: =IF(L33="","",_xlfn.CONCAT(L33," : ",M33,";")) | P33: =K33 -> Sealing | Q33: =Parameters!E35 -> 105 | R33: =Parameters!F35 -> VSSolValveOpenDP | S33: =IF(R33 = "","",_xlfn.CONCAT(R33," : REAL;")) -> VSSolValveOpenDP : REAL; | U33: SystemReserved34 | V33: =IF(U33 = "","",_xlfn.CONCAT(U33," : REAL;")) -> SystemReserved34 : REAL; | W33: FlagReserved23 | X33: =IF(W33 = "","",_xlfn.CONCAT(W33," : REAL;")) -> FlagReserved23 : REAL;
A34: =SUBSTITUTE(LEFT(Parameters!B36,IF(IFERROR(FIND("[",Parameters!B36),100)>IFERROR(FIND("(",Parameters!B36),100),IFERROR(FIND("(",Parameters!B36),100),IFERROR(FIND("[",Parameters!B36),100))-1)," ","") | C34: =IF(B34="","",_xlfn.CONCAT(B34,"_typ")) | D34: =IF(C34 = "","",_xlfn.CONCAT(C34," : STRUCT END_STRUCT;")) | E34: =IF(B34="","",_xlfn.CONCAT(B34," : ",C34,";")) | F34: =SUBSTITUTE(LEFT(Parameters!C36,IF(IFERROR(FIND("[",Parameters!C36),100)>IFERROR(FIND("(",Parameters!C36),100),IFERROR(FIND("(",Parameters!C36),100),IFERROR(FIND("[",Parameters!C36),100))-1)," ","") | H34: =IF(G34="","",_xlfn.CONCAT(G34,"_typ")) | I34: =IF(H34 = "","",_xlfn.CONCAT(H34," : STRUCT END_STRUCT;")) | J34: =IF(G34="","",_xlfn.CONCAT(G34," : ",H34,";")) | K34: =SUBSTITUTE(LEFT(Parameters!D36,IF(IFERROR(FIND("[",Parameters!D36),100)>IFERROR(FIND("(",Parameters!D36),100),IFERROR(FIND("(",Parameters!D36),100),IFERROR(FIND("[",Parameters!D36),100))-1)," ","") | M34: =IF(L34="","",_xlfn.CONCAT(L34,"_typ")) | N34: =IF(M34 = "","",_xlfn.CONCAT(M34," : STRUCT END_STRUCT;")) | O34: =IF(L34="","",_xlfn.CONCAT(L34," : ",M34,";")) | P34: =K34 | Q34: =Parameters!E36 -> 106 | R34: =Parameters!F36 -> VSSolValveCloseDP | S34: =IF(R34 = "","",_xlfn.CONCAT(R34," : REAL;")) -> VSSolValveCloseDP : REAL; | U34: SystemReserved35 | V34: =IF(U34 = "","",_xlfn.CONCAT(U34," : REAL;")) -> SystemReserved35 : REAL; | W34: FlagReserved24 | X34: =IF(W34 = "","",_xlfn.CONCAT(W34," : REAL;")) -> FlagReserved24 : REAL;
A35: =SUBSTITUTE(LEFT(Parameters!B37,IF(IFERROR(FIND("[",Parameters!B37),100)>IFERROR(FIND("(",Parameters!B37),100),IFERROR(FIND("(",Parameters!B37),100),IFERROR(FIND("[",Parameters!B37),100))-1)," ","") | C35: =IF(B35="","",_xlfn.CONCAT(B35,"_typ")) | D35: =IF(C35 = "","",_xlfn.CONCAT(C35," : STRUCT END_STRUCT;")) | E35: =IF(B35="","",_xlfn.CONCAT(B35," : ",C35,";")) | F35: =SUBSTITUTE(LEFT(Parameters!C37,IF(IFERROR(FIND("[",Parameters!C37),100)>IFERROR(FIND("(",Parameters!C37),100),IFERROR(FIND("(",Parameters!C37),100),IFERROR(FIND("[",Parameters!C37),100))-1)," ","") | H35: =IF(G35="","",_xlfn.CONCAT(G35,"_typ")) | I35: =IF(H35 = "","",_xlfn.CONCAT(H35," : STRUCT END_STRUCT;")) | J35: =IF(G35="","",_xlfn.CONCAT(G35," : ",H35,";")) | K35: =SUBSTITUTE(LEFT(Parameters!D37,IF(IFERROR(FIND("[",Parameters!D37),100)>IFERROR(FIND("(",Parameters!D37),100),IFERROR(FIND("(",Parameters!D37),100),IFERROR(FIND("[",Parameters!D37),100))-1)," ","") | M35: =IF(L35="","",_xlfn.CONCAT(L35,"_typ")) | N35: =IF(M35 = "","",_xlfn.CONCAT(M35," : STRUCT END_STRUCT;")) | O35: =IF(L35="","",_xlfn.CONCAT(L35," : ",M35,";")) | P35: =K35 | Q35: =Parameters!E37 -> 107 | R35: =Parameters!F37 -> RTVOpenDP | S35: =IF(R35 = "","",_xlfn.CONCAT(R35," : REAL;")) -> RTVOpenDP : REAL; | U35: SystemReserved36 | V35: =IF(U35 = "","",_xlfn.CONCAT(U35," : REAL;")) -> SystemReserved36 : REAL; | W35: FlagReserved25 | X35: =IF(W35 = "","",_xlfn.CONCAT(W35," : REAL;")) -> FlagReserved25 : REAL;
